Workbook

Sheet 原本
A1: タイムスタンプ | B1: 回答代表者ご氏名 | C1: ご所属施設名 | D1: ご施設の都道府県 | E1: 貴院の理学療法士・作業療法士の代表者メールアドレス | F1: ご所属部署名・職種（任意） | G1: Q1. 2025年1月～12月における大腿骨近位部骨折の症例数を教えてください。（※保存加療症例を含む） | H1: Q2. 2025年1月～12月の期間において、大腿骨近位部骨折を担当した理学療法士（PT）の在籍人数を教えてください。 | I1: Q3. 2025年1月～12月の期間において、大腿骨近位部骨折を担当した作業療法士（OT）の在籍人数を教えてください。 | J1: Q4. 整形外科病棟における「リハビリテーション・栄養・口腔連携体制加算」の算定状況について、令和8年度診療報酬改定の発表前の時点でお答えください。【単一選択】 | K1: Q5. 手術前リハビリテーションで理学療法士または作業療法士が実施している内容を教えてください。【複数選択可】 | L1: Q6. 身体機能（疼痛、筋力低下など）が原因による制限 【4段階評価】 | M1: Q6-1. 「50％〜74％」「75％〜100％」を選択した方にお尋ねします。 →立位が可能になるために貴施設で取り組んでいる対応策を教えてください。【自由記述】 | N1: Q7. 精神・認知機能（認知機能低下、せん妄など）が原因による制限 【4段階評価】 | O1: Q7-1. 「50％〜74％」「75％〜100％」を選択した方にお尋ねします。 →立位が可能になるために貴施設で取り組んでいる対応策を教えてください。【自由記述】 | P1: Q8. 全身状態（呼吸・循環障害、貧血、電解質異常など）が原因による制限 【4段階評価】 | Q1: Q8-1. 「50％〜74％」「75％〜100％」を選択した方にお尋ねします。 →立位が可能になるために貴施設で取り組んでいる対応策を教えてください。【自由記述】 | R1: Q9. 環境的要因（ベッド配置、病室環境、動線などが起因するもの）が原因による制限 【4段階評価】 | S1: Q9-1. 「50％〜74％」「75％〜100％」を選択した方にお尋ねします。 →立位が可能になるために貴施設で取り組んでいる対応策を教えてください。【自由記述】 | T1: Q10． サルコペニアの評価として理学療法士または作業療法士が実施している評価項目を教えてください。 【複数選択可】 | U1: Q10-1 ※「実施していない」を選択した方におたずねします。 → 実施していない理由を教えてください。【自由記述】 | V1: Q11． フレイルの評価として理学療法士または作業療法士が実施している評価項目を教えてください。 【複数選択可】 | W1: Q11-1 ※「実施していない」を選択した方におたずねします。 → 実施していない理由を教えてください。【自由記述】 | X1: Q12． ロコモティブシンドロームの評価として理学療法士または作業療法士が実施している評価項目を教えてください。 【複数選択可】 | Y1: Q12-1 ※「実施していない」を選択した方におたずねします。 → 実施していない理由を教えてください。【自由記述】 | Z1: Q13． ADLの評価として理学療法士または作業療法士が実施している評価項目を教えてください。 【複数選択可】 | AA1: Q13-1 ※「実施していない」を選択した方におたずねします。 → 実施していない理由を教えてください。【自由記述】 | AB1: Q14． 認知機能の評価として理学,作業療法士または言語聴覚士が実施している評価項目を教えてください。 【複数選択可】 | AC1: Q14-1 ※「実施していない」を選択した方におたずねします。 → 実施していない理由を教えてください。【自由記述】 | AD1: Q15． 貴施設のFLS活動の一環として、理学療法士または作業療法士が実施することが施設内で定められている転倒リスク評価項目があれば教えてください。 【複数選択可】 | AE1: Q15-1 ※「実施していない」を選択した方におたずねします。 → 実施していない理由を教えてください。【自由記述】 | AF1: Q15-2 ※「実施している」方におたずねします。 → 評価を実施する時期（術後何日目など）は貴施設のFLS活動として決められていますか。【単一選択】 | AG1: Q15-2-1 ※「決まっている」を選択した方におたずねします。 術後何日目に実施することが決められているか教えてください。【自由記述】 | AH1: Q15-2-2 ※「決まっていない」を選択した方におたずねします。 → 決まっていない理由を教えてください。【自由記述】 | AI1: Q16． 理学療法士または作業療法士が実施している転倒予防策について教えてください。 【複数選択可】 | AJ1: Q16-1 ※「実施していない」を選択した方におたずねします。 → 実施していない理由を教えてください。【自由記述】
A2: 46066.423 | B2: 高野義隆 | C2: 新潟リハビリテーション病院 | D2: 新潟県 | E2: yoshitaka.takano@aiko.or.jp | F2: リハビリテーション部/理学療法士 | G2: 160 | H2: 28 | I2: 18 | J2: 届け出をしておらず、検討もしていない | K2: 関節可動域運動, 筋力増強運動, ポジショニング | L2: 全症例の25％〜49％程度 | N2: 全症例の25％〜49％程度 | P2: 全症例の25％〜49％程度 | R2: 全症例の0％〜24％程度 | T2: 握力, 5回椅子立ち上がりテスト, 歩行速度, SPPB, TUG, 6分間歩行距離 | V2: TUG, 6分間歩行距離, 認知機能 | X2: 実施していない | Y2: 適応となる患者が少ない | Z2: FIM | AB2: MMSE, AMTS | AD2: TUG, SPPB、Functional Reach Test（FRT）, 5回椅子立ち上がりテスト, 認知機能, せん妄, 過去の転倒歴, 既往疾患の有無（脳血管疾患、パーキンソン病など）, 薬剤（向精神薬、降圧薬、利尿薬、ポリファーマシーなど）, ベッド周囲および病室環境 | AF2: 決まっている | AG2: １４日目 | AI2: 下肢筋力強化, バランス練習, 歩行練習, 起立、着座動作練習, 環境調整, 補助具、装具の適正化, 認知面への介入, 教育、指導
A3: 46068.9 | B3: 田中暢一 | C3: ベルランド総合病院 | D3: 大阪府 | E3: goddess.arisa.showmaking@gmail.com | F3: 理学療法室/理学療法士 | G3: 290 | H3: 18 | I3: 8 | J3: 届け出をしておらず、検討もしていない | K3: 関節可動域運動, 筋力増強運動, DVT予防, リラクセーション, ポジショニング, 自主運動指導, 術後リハビリテーションのオリエンテーション | L3: 全症例の0％〜24％程度 | N3: 全症例の0％〜24％程度 | P3: 全症例の0％〜24％程度 | R3: 全症例の0％〜24％程度 | T3: 握力, 開眼片脚立位時間, 下腿周径 | V3: 握力 | X3: ロコモ25（質問票） | Z3: Barthel Index（BI）, FIM | AB3: MMSE, HDS-R | AD3: 開眼片脚立位時間, 認知機能, 過去の転倒歴, SIDE | AF3: 決まっている | AG3: 7日目 | AI3: 下肢筋力強化, バランス練習, 歩行練習, 起立、着座動作練習, 環境調整, 補助具、装具の適正化, 認知面への介入, 教育、指導
A4: 46069.04 | B4: 丸貴仁 | C4: 所沢白翔会病院 | D4: 埼玉県 | E4: t.maru@hakusyoukai.com | F4: リハビリテーション科、事務部／理学療法士 | G4: 60 | H4: 13 | I4: 6 | J4: 届け出はしていないが、現在検討中である | K4: 関節可動域運動, 筋力増強運動, DVT予防, リラクセーション, ポジショニング, 自主運動指導, 術後リハビリテーションのオリエンテーション | L4: 全症例の75％〜100％程度 | M4: 術前リハビリ（受傷前ADL確認含め）、医師等との情報交換 | N4: 全症例の0％〜24％程度 | P4: 全症例の0％〜24％程度 | R4: 全症例の0％〜24％程度 | T4: 握力, 5回椅子立ち上がりテスト, 歩行速度, TUG, 開眼片脚立位時間, 骨格筋量指数（SMI） | V4: Kihon Checklist（基本チェックリスト）, TUG, 認知機能, 抑うつや意欲低下 | X4: 立ち上がりテスト | Z4: Barthel Index（BI）, FIM | AB4: MMSE, AMTS | AD4: 定量的な下肢筋力測定, 開眼片脚立位時間, TUG, 10m歩行速度, 深部感覚評価, 認知機能, 過去の転倒歴, 既往疾患の有無（脳血管疾患、パーキンソン病など）, 薬剤（向精神薬、降圧薬、利尿薬、ポリファーマシーなど）, ベッド周囲および病室環境 | AF4: 決まっている | AG4: 可能となった日 | AI4: 下肢筋力強化, バランス練習, 歩行練習, 歩容改善, 起立、着座動作練習, 環境調整, 補助具、装具の適正化, 認知面への介入, 薬剤調整, 教育、指導
A5: 46069.136 | B5: 吉井智晴 | C5: 東京医療病院 | D5: 東京都 | E5: c-yoshii@u-ths.ac.jp | F5: リハビリテーション学科 理学療法士 | G5: 100 | H5: 15 | I5: 6 | J5: 現在、算定している | K5: 筋力増強運動, 術後リハビリテーションのオリエンテーション | L5: 全症例の25％〜49％程度 | N5: 全症例の50％〜74％程度 | P5: 全症例の25％〜49％程度 | R5: 全症例の25％〜49％程度 | T5: 握力, 膝伸展筋力 | V5: J-CHS基準, Kihon Checklist（基本チェックリスト） | X5: ロコモ25（質問票） | Z5: Barthel Index（BI） | AB5: HDS-R | AD5: 10m歩行速度 | AF5: 決まっている | AI5: 下肢筋力強化, バランス練習
A6: 46069.461 | B6: 渡邊啓太 | C6: 国家公務員共済組合連合会呉共済病院 | D6: 広島県 | E6: tabe19891204@gmail.com | F6: リハビリテーション科／理学療法士 | G6: 168 | H6: 6 | I6: 8 | J6: 届け出をしておらず、検討もしていない | K6: 関節可動域運動, 筋力増強運動, DVT予防, ポジショニング, 自主運動指導, 術後リハビリテーションのオリエンテーション | L6: 全症例の25％〜49％程度 | N6: 全症例の25％〜49％程度 | P6: 全症例の25％〜49％程度 | R6: 全症例の25％〜49％程度 | T6: 握力, 膝伸展筋力, 歩行速度, 開眼片脚立位時間, 骨格筋量指数（SMI） | V6: 認知機能, 握力 | X6: 実施していない | Z6: Barthel Index（BI）, FIM | AB6: HDS-R, AMTS | AD6: 定量的な下肢筋力測定, 開眼片脚立位時間, 10m歩行速度, 認知機能, 過去の転倒歴 | AF6: 決まっている | AG6: 14日目 | AI6: 下肢筋力強化, バランス練習, 歩行練習, 起立、着座動作練習, 環境調整, 補助具、装具の適正化, 認知面への介入, 教育、指導
A7: 46083.633 | B7: 上原 光司 | C7: 社会医療法人愛仁会 高槻病院 | D7: 大阪府 | E7: uehara.kouji@aijinkai-group.com | F7: リハビリテーション科 理学療法士 | G7: 100 | H7: 25 | I7: 10 | J7: 現在、算定している | K7: 関節可動域運動, 筋力増強運動, 呼吸リハビリテーション, DVT予防, ポジショニング, 自主運動指導, 術後リハビリテーションのオリエンテーション | L7: 全症例の25％〜49％程度 | N7: 全症例の0％〜24％程度 | P7: 全症例の0％〜24％程度 | R7: 全症例の0％〜24％程度 | T7: 膝伸展筋力, 歩行速度, 骨格筋量指数（SMI） | V7: 実施していない | X7: 実施していない | Z7: FIM | AB7: MMSE | AD7: 定量的な下肢筋力測定 | AF7: わからない | AI7: 下肢筋力強化, バランス練習, 歩行練習
A8: 46083.663 | B8: 芝原孝治 | C8: 済生会兵庫県病院 | D8: 兵庫県 | E8: shiba20131946@gmail.com | F8: 芝原孝治 | G8: 146 | H8: 11 | I8: 1 | J8: 届け出はしていないが、現在検討中である | K8: DVT予防, ポジショニング, 自主運動指導, 術後リハビリテーションのオリエンテーション, 認知機能評価 | L8: 全症例の75％〜100％程度 | M8: 基本的に術後翌日は疼痛が強いことが多くパスで端座位までとしており、認知機能低下やせん妄予防のため指示がある際に車椅子移乗まで実施している。 | N8: 全症例の0％〜24％程度 | P8: 全症例の0％〜24％程度 | R8: 全症例の0％〜24％程度 | T8: 5回椅子立ち上がりテスト, 歩行速度, SPPB, TUG, 6分間歩行距離, 下腿周径 | V8: TUG, 6分間歩行距離, 認知機能 | X8: 実施していない | Y8: これまではロコモ外来がなく、リハビリを提供していなかったため | Z8: Barthel Index（BI）, FIM | AB8: MMSE, HDS-R, AMTS | AD8: 定量的な下肢筋力測定, TUG, 10m歩行速度, SPPB、Functional Reach Test（FRT）, 認知機能, 過去の転倒歴, 既往疾患の有無（脳血管疾患、パーキンソン病など）, 薬剤（向精神薬、降圧薬、利尿薬、ポリファーマシーなど）, ベッド周囲および病室環境 | AF8: 決まっている | AG8: 術前1日目にAMTS、転倒歴、既往歴など評価し、術後歩行が可能になった時期に応じて歩行速度など実施。 | AI8: 下肢筋力強化, バランス練習, 歩行練習, 歩容改善, 起立、着座動作練習, 環境調整, 補助具、装具の適正化, 認知面への介入, 行動面への介入, 薬剤調整, 教育、指導
A9: 46083.669 | B9: 中野圭介 | C9: 藤沢市民病院 | D9: 神奈川県 | E9: nakano.k0423@gmail.com | F9: 理学療法士 | G9: 20 | H9: 5 | I9: 0 | J9: 届け出はしていないが、現在検討中である | K9: 実施していない | L9: 全症例の0％〜24％程度 | N9: 全症例の0％〜24％程度 | P9: 全症例の0％〜24％程度 | R9: 全症例の0％〜24％程度 | T9: 実施していない | U9: 栄養面では栄養士がやっている | V9: 実施していない | X9: 実施していない | Y9: 必要を感じていない | Z9: Barthel Index（BI） | AB9: MMSE, HDS-R | AD9: 認知機能, 注意障害, せん妄 | AF9: 決まっていない | AH9: 特に理由はない | AI9: 下肢筋力強化, バランス練習, 歩行練習, 歩容改善, 起立、着座動作練習, 環境調整, 補助具、装具の適正化, 認知面への介入, 行動面への介入, 薬剤調整, 教育、指導
A10: 46083.696 | B10: 寺井 真人 | C10: 社会医療法人蒼生会蒼生病院 | D10: 大阪府 | E10: riha@sousei-hp.jp | F10: リハビリテーション科 作業療法士 | G10: 125 | H10: 9 | I10: 2 | J10: 届け出はしているが、算定していない | K10: 関節可動域運動, 筋力増強運動, 術後リハビリテーションのオリエンテーション | L10: 全症例の0％〜24％程度 | N10: 全症例の50％〜74％程度 | O10: 対策はできていないです。指示が入らず拒否が強いことが多いです。 | P10: 全症例の0％〜24％程度 | R10: 全症例の0％〜24％程度 | T10: 握力, 5回椅子立ち上がりテスト, TUG, 開眼片脚立位時間, MNA-SF | V10: 認知機能, 握力 | X10: 実施していない | Y10: フレイルとサルコペニアで対応しています | Z10: Barthel Index（BI） | AB10: MMSE, AMTS | AD10: 開眼片脚立位時間, TUG, 5回椅子立ち上がりテスト, 認知機能 | AF10: 決まっていない | AH10: 各患者状態が違うため。退院1週前～で評価することが多いです | AI10: 下肢筋力強化, バランス練習, 歩行練習, 歩容改善, 起立、着座動作練習, 環境調整, 補助具、装具の適正化, 認知面への介入, 教育、指導
A11: 46083.705 | B11: 高橋智子 | C11: 国立長寿医療研究センター | D11: 愛知県 | E11: ttomoko@ncgg.go.jp | F11: リハビリテーション科部 理学療法士 | G11: 75 | H11: 9 | I11: 3 | J11: 現在、算定している | K11: 関節可動域運動, リラクセーション, ポジショニング | L11: 全症例の0％〜24％程度 | N11: 全症例の50％〜74％程度 | P11: 全症例の25％〜49％程度 | R11: 全症例の25％〜49％程度 | S11: 初回離床はセラピストが介入するようにし、その場で環境設定をおこないます | T11: 握力, 膝伸展筋力, 歩行速度, SPPB, 骨格筋量指数（SMI）, 下腿周径 | V11: TUG, 認知機能, 握力 | X11: 2ステップテスト | Z11: Barthel Index（BI）, FIM | AB11: MMSE | AD11: TUG, 10m歩行速度, SPPB、Functional Reach Test（FRT）, 認知機能, 注意障害, 過去の転倒歴, SIDE | AF11: 決まっていない | AH11: 疼痛により個人差があるため | AI11: 下肢筋力強化, バランス練習, 歩行練習, 起立、着座動作練習, 環境調整, 補助具、装具の適正化
A12: 46083.738 | B12: 下門 範子 | C12: 北九州総合病院 | D12: 福岡県 | E12: n-shimokado@kitakyu-hp.or.jp | F12: リハビリテーション科/作業療法士 | G12: 247 | H12: 8 | I12: 3 | J12: 届け出はしていないが、現在検討中である | K12: DVT予防, ポジショニング, 自主運動指導, 術後リハビリテーションのオリエンテーション, 離床（例：車椅子移乗,立位,歩行など）, 認知症検査（HDS-R/AMTS） | L12: 全症例の0％〜24％程度 | N12: 全症例の0％〜24％程度 | P12: 全症例の0％〜24％程度 | R12: 全症例の0％〜24％程度 | T12: 下腿周径 | V12: 認知機能 | X12: 立ち上がりテスト | Z12: Barthel Index（BI）, FIM | AB12: MMSE, HDS-R | AD12: 認知機能, ベッド周囲および病室環境 | AF12: 決まっている | AG12: 認知機能評価は術前とENT・転院前です。 | AI12: 下肢筋力強化, バランス練習, 歩行練習, 歩容改善, 起立、着座動作練習, 環境調整, 補助具、装具の適正化, 認知面への介入, 行動面への介入, 薬剤調整, 教育、指導
A13: 46083.865 | B13: 池脇圭司 | C13: 徳島県立中央病院 | D13: 徳島県 | E13: kptaf1117@yahoo.co.jp | F13: リハビリテーション技術科/理学療法士 | G13: 202 | H13: 10 | I13: 6 | J13: 届け出をしておらず、検討もしていない | K13: DVT予防, 自主運動指導, 術後リハビリテーションのオリエンテーション, 離床（例：車椅子移乗,立位,歩行など） | L13: 全症例の75％〜100％程度 | M13: 術後は鎮痛剤を入れて、リハ前に頓服も検討 | N13: 全症例の25％〜49％程度 | P13: 全症例の50％〜74％程度 | Q13: アセスメントし、午前か午後で可能か検討 | R13: 全症例の0％〜24％程度 | T13: 下腿周径, GNRI | V13: 認知機能, GNRI, 握力 | X13: 実施していない | Y13: 術後2週以内には転院になり、評価困難例が多いため | Z13: Barthel Index（BI） | AB13: HDS-R, AMTS | AD13: 開眼片脚立位時間, 認知機能, せん妄, 過去の転倒歴, ベッド周囲および病室環境, SIDE | AF13: 決まっている | AG13: 術後７日目 | AI13: 下肢筋力強化, バランス練習, 歩行練習, 起立、着座動作練習, 環境調整, 教育、指導
A14: 46084.401 | B14: 島岡 秀奉 | C14: 高知県立あき総合病院 | D14: 高知県 | E14: satomi_nonaka@ken2.pref.kochi.lg.jp | G14: 96 | H14: 11 | I14: 5 | J14: 届け出をしておらず、検討もしていない | K14: DVT予防, ポジショニング, 自主運動指導, 術後リハビリテーションのオリエンテーション | L14: 全症例の50％〜74％程度 | M14: 特になし | N14: 全症例の0％〜24％程度 | P14: 全症例の0％〜24％程度 | R14: 全症例の0％〜24％程度 | T14: 握力, 下腿周径 | V14: 認知機能, 握力 | X14: 実施していない | Y14: 回復期のある病院へ転院されることが多く実施できない。 | Z14: Barthel Index（BI）, FIM | AB14: AMTS | AD14: 実施していない | AE14: リハビリ対象の患者が高齢のため大半の患者が転倒リスクが高い | AH14: Q15-1の回答と同様 | AI14: 下肢筋力強化, バランス練習, 歩行練習, 歩容改善, 起立、着座動作練習, 環境調整, 補助具、装具の適正化
A15: 46084.412 | B15: 澤下 浩二 | C15: 甲南医療センタ－ | D15: 兵庫県 | E15: koji.sawashita@kohnan.or.jp | F15: リハビリテーション部/理学療法士 | G15: 146 | H15: 6 | I15: 9 | J15: 届け出はしていないが、現在検討中である | K15: 関節可動域運動, 筋力増強運動, DVT予防, ポジショニング | L15: 全症例の0％〜24％程度 | N15: 全症例の0％〜24％程度 | P15: 全症例の0％〜24％程度 | R15: 全症例の0％〜24％程度 | T15: 握力, 5回椅子立ち上がりテスト, SPPB, 下腿周径 | V15: 握力 | X15: 立ち上がりテスト | Z15: Barthel Index（BI）, FIM | AB15: MMSE | AD15: SPPB、Functional Reach Test（FRT） | AF15: 決まっていない | AI15: 下肢筋力強化, バランス練習, 歩行練習, 環境調整, 補助具、装具の適正化
A16: 46084.415 | B16: 宮澤佑治 | C16: 浜松医療センター | D16: 静岡県 | E16: amakoa@yahoo.co.jp | F16: リハビリテーション技術科/理学療法士 | G16: 350 | H16: 15 | I16: 7 | J16: 届け出をしておらず、検討もしていない | K16: DVT予防, リラクセーション, 離床（例：車椅子移乗,立位,歩行など） | L16: 全症例の75％〜100％程度 | M16: 医師による強力な促しがあります。暴れてうまくいかない人は人数かけて行う事もあります。術翌日は最低座位、車椅子乗車まで行うのが普通でそれができない人は免荷が必要な過体重な人か重度脳卒中併存、暴れるなどの人であることが多いのでそういう人をそこまでするか？は適宜判断して行います。 | N16: 全症例の0％〜24％程度 | P16: 全症例の0％〜24％程度 | Q16: 貧血が原因であれば輸血した後に起立する、短時間にする、起立よりも座位時間確保など | R16: 全症例の0％〜24％程度 | T16: 握力, 歩行速度, 下腿周径 | U16: 人によります。高齢で明らかに弱々しい人は測定しますが元気な人は定型的に行わないこともあります。 | V16: J-CHS基準, 認知機能, 握力 | W16: 頸部骨折にはフレイルが関連している可能性が高いから全例スクリーニングしましょうという高度なことはできていません。各担当者がありそうだな、と感じた場合上記評価を適宜行っています。 | X16: 実施していない | Y16: ロコモティブシンドロームとしては評価スクリーニングしてません。当院ではロコモはそれほど議論されていません。 | Z16: Barthel Index（BI） | AB16: MMSE | AC16: 大腿骨骨折はパス化されていますが近隣のリハビリテーション病院がmmseやらないととらないなどわがままをいうのでよほど元気で認知症扱いするなと怒る人以外はスクリーニングとしてとっています。 | AD16: Berg Balance Scale（BBS）, SPPB、Functional Reach Test（FRT）, せん妄, 過去の転倒歴, 既往疾患の有無（脳血管疾患、パーキンソン病など）, 薬剤（向精神薬、降圧薬、利尿薬、ポリファーマシーなど）, ベッド周囲および病室環境 | AF16: 決まっていない | AH16: 症例数が多すぎるので、院内転倒リスクが高いとnsかリハでおもったひとを抽出して井戸端会議したり転んでしまった人は事案発覚からすぐに集まってカンファします。これも病棟でまちまちなこともあります。 | AI16: 下肢筋力強化, バランス練習, 歩行練習, 歩容改善, 起立、着座動作練習, 環境調整, 補助具、装具の適正化, 教育、指導 | AJ16: 転倒予防策として定型的に行っているものはありません。担当者の裁量で行っていることが多く組織的にできていないのは課題と考えます。組織的に行っていないというのがこの設問の行っていないに該当するのであれば行っていません。
A17: 46084.444 | B17: 水谷純子 | C17: 東京都済生会中央病院 | D17: 東京都 | E17: rh-mizutani@saichu.jp | F17: リハビリテーション技術科／理学療法士 | G17: 78 | H17: 9 | I17: 5 | J17: 届け出をしておらず、検討もしていない | K17: 実施していない | L17: 全症例の0％〜24％程度 | N17: 全症例の0％〜24％程度 | P17: 全症例の0％〜24％程度 | R17: 全症例の0％〜24％程度 | T17: 実施していない | U17: 3次救急で大腿骨近位部骨折の患者にフレイルの評価としては時期的に取っていない。機能評価としてはやっています。 | V17: 実施していない | W17: 3次救急で大腿骨近位部骨折の患者にフレイルの評価としては時期的に取っていない。機能評価としてはやっています。 | X17: 実施していない | Y17: 3次救急で大腿骨近位部骨折の患者であり、評価の時期まで入院していない。 | Z17: Barthel Index（BI） | AB17: MMSE, HDS-R, MoCA, AMTS | AD17: TUG, 10m歩行速度, Berg Balance Scale（BBS）, SPPB、Functional Reach Test（FRT）, 深部感覚評価, 認知機能, せん妄, 過去の転倒歴, 既往疾患の有無（脳血管疾患、パーキンソン病など） | AF17: 決まっている | AG17: TUGは7POD、AMTSは10POD、それ以外は患者に合わせてできる時期に評価 | AI17: 下肢筋力強化, バランス練習, 歩行練習, 歩容改善, 起立、着座動作練習, 環境調整, 補助具、装具の適正化, 認知面への介入, 薬剤調整, 教育、指導
A18: 46084.478 | B18: 望月拓駿 | C18: 静岡県立総合病院 | D18: 静岡県 | E18: omochitack14@gmail.com | F18: リハビリテーション科/理学療法士 | G18: 140 | H18: 25 | I18: 0 | J18: 届け出はしていないが、現在検討中である | K18: 関節可動域運動, 筋力増強運動, DVT予防, 自主運動指導, 術後リハビリテーションのオリエンテーション | L18: 全症例の25％〜49％程度 | N18: 全症例の25％〜49％程度 | P18: 全症例の0％〜24％程度 | R18: 全症例の0％〜24％程度 | T18: 握力, 歩行速度, SPPB | V18: 認知機能, 握力 | X18: 実施していない | Y18: 当院として計測を行っていない | Z18: Barthel Index（BI）, FIM | AB18: MMSE, HDS-R | AD18: TUG, Berg Balance Scale（BBS）, SPPB、Functional Reach Test（FRT）, ベッド周囲および病室環境 | AF18: 決まっていない | AH18: 実際の患者に合わせて可能かどうかを各自判断している | AI18: 下肢筋力強化, バランス練習, 歩行練習, 起立、着座動作練習, 環境調整, 補助具、装具の適正化, 認知面への介入, 行動面への介入
A19: 46084.484 | B19: 三浦大介 | C19: 地方独立行政法人 岐阜県立多治見病院 | D19: 岐阜県 | E19: miura-daisuke@tajimi-hospital.jp | F19: リハビリテーション科 理学療法士 | G19: 159 | H19: 10 | I19: 0 | J19: 届け出をしておらず、検討もしていない | K19: 関節可動域運動, 筋力増強運動, 呼吸リハビリテーション, DVT予防, 自主運動指導, 術後リハビリテーションのオリエンテーション, 離床（例：車椅子移乗,立位,歩行など） | L19: 全症例の50％〜74％程度 | M19: 鎮痛薬による疼痛コントロール 高頻度介入 | N19: 全症例の25％〜49％程度 | P19: 全症例の0％〜24％程度 | R19: 全症例の0％〜24％程度 | T19: SPPB, TUG, 6分間歩行距離 | V19: TUG, 6分間歩行距離, 認知機能 | X19: 実施していない | Z19: Barthel Index（BI） | AB19: HDS-R, AMTS | AD19: TUG, SPPB、Functional Reach Test（FRT）, 認知機能, せん妄, 既往疾患の有無（脳血管疾患、パーキンソン病など）, 薬剤（向精神薬、降圧薬、利尿薬、ポリファーマシーなど）, ベッド周囲および病室環境 | AF19: 決まっている | AG19: 退院時 | AI19: 下肢筋力強化, バランス練習, 歩行練習, 歩容改善, 起立、着座動作練習, 環境調整, 補助具、装具の適正化, 認知面への介入
A20: 46084.56 | B20: 永松 康太 | C20: 神奈川県厚生連 伊勢原協同病院 | D20: 神奈川県 | E20: kotadk.h@gmail.com | F20: リハビリテーション室/理学療法士 | G20: 189 | H20: 7 | I20: 4 | J20: 届け出をしておらず、検討もしていない | K20: 関節可動域運動, 筋力増強運動, DVT予防, リラクセーション, ポジショニング, 自主運動指導, 術後リハビリテーションのオリエンテーション | L20: 全症例の0％〜24％程度 | N20: 全症例の0％〜24％程度 | P20: 全症例の0％〜24％程度 | R20: 全症例の0％〜24％程度 | T20: 膝伸展筋力, 歩行速度 | V20: 認知機能 | X20: 実施していない | Y20: 理由は特にありません | Z20: Barthel Index（BI） | AB20: HDS-R, AMTS | AD20: 定量的な下肢筋力測定, 認知機能, 過去の転倒歴, 既往疾患の有無（脳血管疾患、パーキンソン病など）, 薬剤（向精神薬、降圧薬、利尿薬、ポリファーマシーなど）, ベッド周囲および病室環境 | AF20: 決まっていない | AH20: 通常の理学療法評価の中で行うため、特に決まっていません。 | AI20: 下肢筋力強化, バランス練習, 歩行練習, 歩容改善, 起立、着座動作練習, 環境調整
A21: 46084.577 | B21: 高橋智之 | C21: 関口病院 | D21: 群馬県 | E21: t.takahashi@kouwa-sekiguchi.com | F21: リハビリテーション課/理学療法士 | G21: 189 | H21: 20 | I21: 0 | J21: 届け出をしておらず、検討もしていない | K21: 関節可動域運動, 筋力増強運動, 呼吸リハビリテーション, DVT予防, リラクセーション, ポジショニング, 離床（例：車椅子移乗,立位,歩行など） | L21: 全症例の0％〜24％程度 | N21: 全症例の0％〜24％程度 | P21: 全症例の0％〜24％程度 | R21: 全症例の0％〜24％程度 | T21: 握力, 膝伸展筋力, 5回椅子立ち上がりテスト, 6分間歩行距離, 下腿周径 | V21: 握力 | X21: 立ち上がりテスト | Z21: Barthel Index（BI）, FIM | AB21: HDS-R | AD21: 定量的な下肢筋力測定, 5回椅子立ち上がりテスト, 過去の転倒歴, 既往疾患の有無（脳血管疾患、パーキンソン病など）, 薬剤（向精神薬、降圧薬、利尿薬、ポリファーマシーなど） | AF21: 決まっていない | AH21: 退院前に一回実施するため、患者によって実施するタイミングが異なるから | AI21: 下肢筋力強化, バランス練習, 歩行練習, 歩容改善, 起立、着座動作練習, 環境調整, 行動面への介入, 教育、指導
A22: 46084.581 | B22: 藤野裕気 | C22: 医療法人吉野会はやと整形外科 | D22: 鹿児島県 | E22: hayatoseikei-riha@po2.synapse.ne.jp | F22: リハビリテーション科/理学療法士 | G22: 27 | H22: 7 | I22: 1 | J22: 届け出はしていないが、現在検討中である | K22: 関節可動域運動, 筋力増強運動, DVT予防, リラクセーション, ポジショニング, 自主運動指導, 術後リハビリテーションのオリエンテーション | L22: 全症例の25％〜49％程度 | N22: 全症例の25％〜49％程度 | P22: 全症例の25％〜49％程度 | R22: 全症例の0％〜24％程度 | T22: 握力, 5回椅子立ち上がりテスト, TUG, 開眼片脚立位時間, 下腿周径 | V22: TUG, 握力 | X22: 立ち上がりテスト, 2ステップテスト | Z22: Barthel Index（BI）, FIM | AB22: 実施していない | AC22: 看護師がAMTSまたはHDS-Rを実施している為 | AD22: 開眼片脚立位時間, TUG, 5回椅子立ち上がりテスト, Fall Risk Index | AF22: 決まっていない | AH22: 患者様により立位や歩行できる時期が異なる為 | AI22: 下肢筋力強化, バランス練習, 歩行練習, 歩容改善, 起立、着座動作練習, 環境調整, 補助具、装具の適正化, 行動面への介入, 教育、指導
A23: 46084.592 | B23: 今井智文 | C23: 豊川市民病院 | D23: 愛知県 | E23: reha@toyokawa-ch-aichi.jp | F23: リハビリテーション技術科/理学療法士 | G23: 229 | H23: 18 | I23: 8 | J23: 届け出をしておらず、検討もしていない | K23: 筋力増強運動, DVT予防, リラクセーション, ポジショニング, 自主運動指導, 術後リハビリテーションのオリエンテーション | L23: 全症例の25％〜49％程度 | N23: 全症例の0％〜24％程度 | P23: 全症例の0％〜24％程度 | R23: 全症例の0％〜24％程度 | T23: 実施していない | U23: 術前はベッド上安静で評価実施困難。（座位・起立・歩行は困難）術後は機能回復のための介入が中心となります。 | V23: 実施していない | W23: 術前はベッド上安静で評価実施困難。（座位・起立・歩行は困難）術後は機能回復のための介入が中心となります。 | X23: 実施していない | Y23: 術前はベッド上安静で評価実施困難。（座位・起立・歩行は困難）術後は機能回復のための介入が中心となります。 | Z23: Barthel Index（BI）, FIM | AB23: MMSE, HDS-R, AMTS | AD23: 定量的な下肢筋力測定, 認知機能, 注意障害, ベッド周囲および病室環境, 転倒予防カンファレンスへの参加 | AF23: 決まっている | AG23: 術後３日以内 | AI23: 下肢筋力強化, バランス練習, 歩行練習, 歩容改善, 起立、着座動作練習, 環境調整, 補助具、装具の適正化, 認知面への介入, 行動面への介入, 教育、指導
A24: 46084.595 | B24: 屋宜 秀明 | C24: 徳島市民病院 | D24: 徳島県 | E24: hideaki_rx78@yahoo.co.jp | F24: リハビリテーション科／理学療法士 | G24: 203 | H24: 13 | I24: 0 | J24: 届け出をしておらず、検討もしていない | K24: 関節可動域運動, DVT予防, ポジショニング, 自主運動指導, 術後リハビリテーションのオリエンテーション | L24: 全症例の25％〜49％程度 | N24: 全症例の0％〜24％程度 | P24: 全症例の0％〜24％程度 | R24: 全症例の0％〜24％程度 | T24: 握力, 下腿周径 | V24: 握力 | X24: 実施していない | Z24: Barthel Index（BI） | AB24: MMSE, HDS-R | AD24: 実施していない | AE24: 各セラピストが評価を行い訓練を実施していますが、特定の評価を必須にはしてません。 | AI24: 下肢筋力強化, バランス練習, 歩行練習, 環境調整
A25: 46084.647 | B25: 荒木 裕介 | C25: 医療法人 讃高会 枚方東整形外科病院 | D25: 大阪府 | E25: takai.rihabiri@sankokai.or.jp | F25: リハビリテーション室/理学療法士 | G25: 106 | H25: 9 | I25: 0 | J25: 届け出をしておらず、検討もしていない | K25: 関節可動域運動, 筋力増強運動, リラクセーション, ポジショニング | L25: 全症例の0％〜24％程度 | N25: 全症例の0％〜24％程度 | P25: 全症例の0％〜24％程度 | R25: 全症例の0％〜24％程度 | T25: 握力, 膝伸展筋力, 歩行速度 | V25: 抑うつや意欲低下, 握力 | X25: 実施していない | Z25: Barthel Index（BI）, FIM | AB25: 実施していない | AD25: 実施していない | AE25: 片脚立位等，各々で評価はしているが，施設して定められた評価は無い | AI25: 下肢筋力強化, バランス練習, 歩行練習, 歩容改善, 起立、着座動作練習, 環境調整, 教育、指導
A26: 46084.67 | B26: 堂前 伸 | C26: 東京歯科大学市川総合病院 | D26: 千葉県 | E26: sdoumae@tdc.ac.jp | F26: リハビリテーション科/理学療法士 | G26: 52 | H26: 7 | I26: 0 | J26: 届け出をしておらず、検討もしていない | K26: 術前評価のみ | L26: 全症例の0％〜24％程度 | N26: 全症例の0％〜24％程度 | P26: 全症例の0％〜24％程度 | R26: 全症例の0％〜24％程度 | T26: 握力, 膝伸展筋力, 5回椅子立ち上がりテスト, 歩行速度, TUG, 開眼片脚立位時間, 下腿周径 | V26: TUG, 6分間歩行距離, 認知機能, 握力 | X26: 立ち上がりテスト, ロコモ25（質問票） | Z26: Barthel Index（BI）, FIM | AB26: MMSE, HDS-R | AD26: 認知機能, せん妄, 過去の転倒歴, 既往疾患の有無（脳血管疾患、パーキンソン病など）, 薬剤（向精神薬、降圧薬、利尿薬、ポリファーマシーなど）, ベッド周囲および病室環境 | AF26: 決まっていない | AH26: 動作獲得に個人差があるため、立位・歩行が可能となったタイミングで実施 | AI26: 下肢筋力強化, バランス練習, 歩行練習, 起立、着座動作練習, 環境調整
A27: 46084.692 | B27: 木ノ下哲嗣 | C27: 手稲渓仁会病院 | D27: 北海道 | E27: kinoshita-sat@keijinkai.or.jp | F27: リハビリテーション部/理学療法士 | G27: 70 | H27: 13 | I27: 4 | J27: 届け出をしておらず、検討もしていない | K27: 関節可動域運動, 筋力増強運動, 呼吸リハビリテーション, DVT予防, リラクセーション, ポジショニング, 自主運動指導, 術後リハビリテーションのオリエンテーション, 離床（例：車椅子移乗,立位,歩行など） | L27: 全症例の25％〜49％程度 | N27: 全症例の0％〜24％程度 | P27: 全症例の0％〜24％程度 | R27: 全症例の0％〜24％程度 | T27: 膝伸展筋力, 歩行速度, TUG | V27: J-CHS基準, 認知機能, 抑うつや意欲低下 | X27: 実施していない | Z27: Barthel Index（BI）, FIM | AB27: MMSE, AMTS | AD27: 定量的な下肢筋力測定, TUG, 10m歩行速度, Berg Balance Scale（BBS） | AF27: 決まっている | AG27: 術前もしくは術後１日目 | AI27: 下肢筋力強化, バランス練習, 歩行練習, 歩容改善, 起立、着座動作練習, 環境調整, 認知面への介入
A28: 46084.713 | B28: 山下 麻美 | C28: 済生会長崎病院 | D28: 長崎県 | E28: mami.saisei.0913@gmail.com | F28: リハビリテーション部／理学療法士 | G28: 239 | H28: 14 | I28: 0 | J28: 届け出をしておらず、検討もしていない | K28: 関節可動域運動, 筋力増強運動, DVT予防, リラクセーション, ポジショニング, 自主運動指導, 術後リハビリテーションのオリエンテーション | L28: 全症例の75％〜100％程度 | M28: 術後翌日からのリハビリテーションの介入。 | N28: 全症例の0％〜24％程度 | P28: 全症例の0％〜24％程度 | R28: 全症例の0％〜24％程度 | T28: 実施していない | U28: その他評価で対応。 | V28: 実施していない | W28: その他評価で対応。 | X28: 実施していない | Y28: その他評価で対応。 | Z28: Barthel Index（BI） | AB28: MMSE, HDS-R, MoCA | AD28: 実施していない | AE28: 患者によって、必要な評価を選定して行っている。 | AH28: 同じ病名でも、年齢や性別等患者背景が異なるため。 | AI28: 下肢筋力強化, バランス練習, 歩行練習, 歩容改善, 起立、着座動作練習, 環境調整, 補助具、装具の適正化, 認知面への介入, 行動面への介入, 薬剤調整, 教育、指導
A29: 46084.723 | B29: 岡野宏信 | C29: 香川県立中央病院 | D29: 香川県 | E29: oknhiron@gmail.com | F29: リハビリテーション部/理学療法士 | G29: 138 | H29: 8 | I29: 0 | J29: 届け出をしておらず、検討もしていない | K29: 関節可動域運動, 筋力増強運動, 呼吸リハビリテーション, DVT予防, リラクセーション, ポジショニング, 自主運動指導, 術後リハビリテーションのオリエンテーション | L29: 全症例の25％〜49％程度 | N29: 全症例の25％〜49％程度 | P29: 全症例の25％〜49％程度 | R29: 全症例の0％〜24％程度 | T29: 握力, 歩行速度 | V29: 実施していない | W29: データを利用していないため | X29: 実施していない | Y29: データを利用していないため。 | Z29: Barthel Index（BI） | AB29: AMTS | AD29: 10m歩行速度, | AF29: 決まっている | AG29: 14日目を目安に行っている | AI29: 下肢筋力強化, バランス練習, 歩行練習, 歩容改善, 起立、着座動作練習, 環境調整, 補助具、装具の適正化, 認知面への介入, 行動面への介入, 薬剤調整, 教育、指導
A30: 46084.754 | B30: 藤井千博 | C30: 総合病院 聖隷浜松病院 | D30: 静岡県 | E30: c-fujii@sis.seirei.or.jp | F30: リハビリテーション部／理学療法士 | G30: 211 | H30: 10 | I30: 5 | J30: 届け出はしていないが、現在検討中である | K30: 実施していない | L30: 全症例の0％〜24％程度 | N30: 全症例の0％〜24％程度 | P30: 全症例の0％〜24％程度 | R30: 全症例の0％〜24％程度 | T30: 実施していない | U30: サルコペニアに特化した評価は実施していない 各症例に必要な評価を実施している | V30: 実施していない | W30: フレイルに特化した評価は実施していない 各症例に必要な評価を実施している | X30: 実施していない | Y30: ロコモに特化した評価は実施していない 各症例に必要な評価を実施している | Z30: Barthel Index（BI） | AB30: MMSE, AMTS | AD30: 実施していない | AE30: 活動の一環としては評価は実施していない 各症例に必要な評価を実施している | AI30: 下肢筋力強化, バランス練習, 歩行練習, 歩容改善, 起立、着座動作練習, 環境調整, 補助具、装具の適正化, 認知面への介入, 行動面への介入, 教育、指導
A31: 46084.769 | B31: 那須崇史 | C31: 重工大須病院 | D31: 愛知県 | E31: t-nasu@keimeikai.or.jp | F31: リハビリテーション部/理学療法士 | G31: 176 | H31: 7 | I31: 2 | J31: 現在、算定している | K31: 関節可動域運動, 筋力増強運動, DVT予防, リラクセーション, ポジショニング, 自主運動指導, 術後リハビリテーションのオリエンテーション, 離床（例：車椅子移乗,立位,歩行など）, リアリティーオリエンテーション | L31: 全症例の0％〜24％程度 | N31: 全症例の0％〜24％程度 | P31: 全症例の0％〜24％程度 | R31: 全症例の0％〜24％程度 | T31: 握力, 歩行速度, TUG, 下腿周径 | V31: TUG, 認知機能, 握力 | X31: 実施していない | Y31: ロコモティブシンドロームとしての評価を設定していないため | Z31: Barthel Index（BI）, FIM | AB31: MMSE, MoCA | AD31: 認知機能, 過去の転倒歴, Fall Risk Index | AF31: 決まっている | AG31: 術前に実施しています。 | AI31: 下肢筋力強化, バランス練習, 歩行練習, 歩容改善, 起立、着座動作練習, 環境調整, 補助具、装具の適正化, 認知面への介入, 行動面への介入, 教育、指導
A32: 46084.802 | B32: 青木 敏明 | C32: 東京都立多摩総合医療センター | D32: 東京都 | E32: toshiaki_aoki@tmhp.jp | F32: リハビリテーション科／理学療法士 | G32: 155 | H32: 18 | I32: 0 | J32: 届け出はしていないが、現在検討中である | K32: 関節可動域運動, 筋力増強運動, DVT予防, 術後リハビリテーションのオリエンテーション, 離床（例：車椅子移乗,立位,歩行など） | L32: 全症例の50％〜74％程度 | M32: 痛みの評価・対症療法（軽めのROM・マッサージ等） | N32: 全症例の50％〜74％程度 | O32: 覚醒状態のタイミングをみて介入 | P32: 全症例の50％〜74％程度 | Q32: 起立性低血圧が多く、段階的な姿勢調整とバイタルチェック | R32: 全症例の0％〜24％程度 | T32: 各種評価は行っているが、サルコペニアの評価としては実施していない | U32: 通常の術後評価のみ行っている | V32: 各種評価は行っているが、フレイルの評価としては実施していない | W32: 通常の術後評価のみ行っている | X32: 各種評価は行っているが、ロコモの評価としては実施していない | Y32: 通常の術後評価のみ行っている | Z32: Barthel Index（BI）, FIM | AB32: HDS-R | AD32: 各種評価は行っているが、特に定められた評価としては実施していない | AE32: 通常の評価として実施している | AF32: 決まっていない | AH32: 患者の状況に応じて評価を実施している | AI32: 下肢筋力強化, バランス練習, 歩行練習, 補助具、装具の適正化, 認知面への介入
A33: 46085.259 | B33: 松尾英明 | C33: 福井大学医学部附属病院 | D33: 福井県 | E33: hideakim@u-fukui.ac.jp | F33: リハビリテーション部/理学療法士 | G33: 136 | H33: 4 | I33: 2 | J33: 届け出をしておらず、検討もしていない | K33: 関節可動域運動, 筋力増強運動, DVT予防, ポジショニング, 自主運動指導, 術後リハビリテーションのオリエンテーション, 離床（例：車椅子移乗,立位,歩行など） | L33: 全症例の0％〜24％程度 | N33: 全症例の0％〜24％程度 | P33: 全症例の0％〜24％程度 | R33: 全症例の0％〜24％程度 | T33: SPPB, SARC-F | V33: Kihon Checklist（基本チェックリスト） | X33: 実施していない | Y33: 時間の十分にとれない急性期リハの中で、フレイル、サルコペニアを優先的に評価しているため。 | Z33: FIM | AB33: HDS-R, AMTS | AD33: 開眼片脚立位時間, 10m歩行速度, Berg Balance Scale（BBS）, SPPB、Functional Reach Test（FRT）, 5回椅子立ち上がりテスト, 深部感覚評価, 認知機能, 注意障害, 遂行機能, せん妄, 転倒恐怖感, 過去の転倒歴, 既往疾患の有無（脳血管疾患、パーキンソン病など）, 薬剤（向精神薬、降圧薬、利尿薬、ポリファーマシーなど）, ベッド周囲および病室環境 | AF33: 決まっていない | AH33: もともとの診療活動として行っているため、FLS活動として改めて決め直していない。 | AI33: 下肢筋力強化, バランス練習, 歩行練習, 歩容改善, 起立、着座動作練習, 環境調整, 補助具、装具の適正化, 認知面への介入, 行動面への介入, 薬剤調整, 教育、指導
A34: 46085.507 | B34: 村山智幸 | C34: 新潟厚生連 上越総合病院 | D34: 新潟県 | E34: murayama-itigo-video1@ezweb.ne.jp | F34: リハビリテーション科 理学療法士 | G34: 137 | H34: 12 | I34: 2 | J34: 届け出はしているが、算定していない | K34: DVT予防, リラクセーション, ポジショニング, 自主運動指導, 術後リハビリテーションのオリエンテーション | L34: 全症例の0％〜24％程度 | N34: 全症例の0％〜24％程度 | P34: 全症例の0％〜24％程度 | R34: 全症例の0％〜24％程度 | T34: 握力, 膝伸展筋力 | V34: TUG, 握力 | X34: 立ち上がりテスト | Z34: Barthel Index（BI）, FIM | AB34: MMSE, HDS-R | AD34: 定量的な下肢筋力測定, 過去の転倒歴 | AF34: 決まっている | AG34: 退院までの期間 | AI34: 下肢筋力強化, バランス練習, 歩行練習, 起立、着座動作練習, 環境調整, 補助具、装具の適正化, 認知面への介入
A35: 46085.552 | B35: 藤野 裕美 | C35: 独立行政法人国立病院機構 四国こどもとおとなの医療センター | D35: 香川県 | E35: fujino.hiromi.qm@hosp.go.jp | F35: リハビリテーション科/理学療法士 | G35: 215 | H35: 6 | I35: 0 | J35: 届け出をしておらず、検討もしていない | K35: 実施していない | L35: 全症例の0％〜24％程度 | N35: 全症例の0％〜24％程度 | P35: 全症例の0％〜24％程度 | R35: 全症例の0％〜24％程度 | T35: 実施していない | U35: 評価を活用できる体制が整っておらず、仕組み作りが今後の課題 | V35: 実施していない | W35: 評価を活用できる体制が整っておらず、仕組み作りが今後の課題 | X35: 実施していない | Y35: 評価を活用できる体制が整っておらず、仕組み作りが今後の課題 | Z35: Barthel Index（BI）, FIM | AB35: MMSE, HDS-R | AD35: 定量的な下肢筋力測定, 認知機能, 転倒恐怖感, 過去の転倒歴, ベッド周囲および病室環境 | AF35: 決まっていない | AH35: 症状を基準に評価しており、業務フローは未整備である | AI35: 下肢筋力強化, バランス練習, 歩行練習, 歩容改善, 起立、着座動作練習, 環境調整, 補助具、装具の適正化, 教育、指導
A36: 46085.605 | B36: 桒原 慶太 | C36: 北里大学メディカルセンター | D36: 埼玉県 | E36: kuwabara@insti.kitasato-u.ac.jp | F36: リハビリテーションセンター・理学療法士 | G36: 98 | H36: 6 | I36: 0 | J36: 届け出をしておらず、検討もしていない | K36: 筋力増強運動, ポジショニング, 自主運動指導 | L36: 全症例の0％〜24％程度 | N36: 全症例の0％〜24％程度 | P36: 全症例の0％〜24％程度 | R36: 全症例の0％〜24％程度 | T36: 実施していない | U36: 握力、膝伸展筋力など上記の上から8つ目までは歩ける患者の多くで体力構成要素の検査として実施していますが、「サルコペニア」の評価としては実施していません。 | V36: 実施していない | W36: フレイルの評価をする視点がないため（フレイルであっても急性発症した疾病や手術後の影響が大きいためその視点でのアセスメントはできないため） | X36: 実施していない | Y36: Q11とおなじ理由 | Z36: Barthel Index（BI）, FIM | AB36: MMSE | AD36: 定量的な下肢筋力測定, 開眼片脚立位時間, TUG, 10m歩行速度, 5回椅子立ち上がりテスト, 認知機能 | AF36: 決まっていない | AH36: 日にちではなく、機能状態の改善程度を参考に決めています。 | AI36: 下肢筋力強化, バランス練習, 歩行練習, 歩容改善, 環境調整, 補助具、装具の適正化, 教育、指導
A37: 46085.654 | B37: 坂本 大和 | C37: 社会医療法人大成会 福岡記念病院 | D37: 福岡県 | E37: yappariyoshida@gmail.com | F37: リハビリテーション科／理学療法士 | G37: 225 | H37: 14 | I37: 9 | J37: 届け出をしておらず、検討もしていない | K37: DVT予防, リラクセーション, ポジショニング, 自主運動指導, 術後リハビリテーションのオリエンテーション, 離床（例：車椅子移乗,立位,歩行など）, 全症例には介入しておらず、入院から手術までの待機期間が長くなるケースのみ術前介入している。 | L37: 全症例の25％〜49％程度 | N37: 全症例の25％〜49％程度 | P37: 全症例の0％〜24％程度 | R37: 全症例の0％〜24％程度 | T37: SPPB, 下腿周径, 急性期病院のため、患者が安全に評価できる状況にない。 | V37: 認知機能 | X37: 実施していない | Y37: スタッフの認識と知識がない。 | Z37: Barthel Index（BI） | AB37: MMSE, HDS-R | AD37: 入院前と退院時の屋内、屋外での歩行状況の評価を実施している。 | AF37: 決まっている | AG37: 退院前には、評価項目を入力するようになっている。 | AI37: 下肢筋力強化, バランス練習, 歩行練習, 歩容改善, 環境調整, 補助具、装具の適正化
A38: 46085.675 | B38: 稲井 勲 | C38: 香川県済生会病院 | D38: 香川県 | E38: saiseikaikagawa@mf.pikara.ne.jp | F38: リハビリテーション科理学療法士 | G38: 64 | H38: 10 | I38: 8 | J38: 届け出はしていないが、現在検討中である | K38: 実施していない | L38: 全症例の0％〜24％程度 | N38: 全症例の0％〜24％程度 | P38: 全症例の0％〜24％程度 | R38: 全症例の0％〜24％程度 | T38: 実施していない, | U38: 個人の評価法による | V38: 実施していない | X38: 実施していない | Z38: FIM | AB38: MMSE, HDS-R | AD38: 実施していない | AI38: 下肢筋力強化, バランス練習, 歩行練習, 環境調整
A39: 46085.68 | B39: 照屋俊樹 | C39: 社会医療法人かりゆし会ハートライフ病院 | D39: 沖縄県 | E39: reha@heartlife.or.jp | F39: リハビリテーション科／理学療法士 | G39: 190 | H39: 15 | I39: 5 | J39: 届け出はしていないが、現在検討中である | K39: 関節可動域運動, 筋力増強運動, DVT予防, リラクセーション, ポジショニング, 術後リハビリテーションのオリエンテーション, 離床（例：車椅子移乗,立位,歩行など） | L39: 全症例の50％〜74％程度 | M39: 早期離床行い、動作能力を看護師へ報告し、トイレ誘導の依頼を行っている | N39: 全症例の25％〜49％程度 | P39: 全症例の25％〜49％程度 | R39: 全症例の0％〜24％程度 | T39: 実施していない | U39: 動作能力の改善度合いで評価しているため | V39: 実施していない | W39: 動作能力の改善度合いで評価しているため | X39: 立ち上がりテスト | Z39: FIM | AB39: MMSE, HDS-R | AD39: 注意障害, せん妄, 過去の転倒歴, 既往疾患の有無（脳血管疾患、パーキンソン病など）, 薬剤（向精神薬、降圧薬、利尿薬、ポリファーマシーなど）, ベッド周囲および病室環境 | AF39: 決まっている | AG39: 毎週 | AI39: 下肢筋力強化, バランス練習, 歩行練習, 歩容改善, 起立、着座動作練習, 環境調整, 補助具、装具の適正化, 認知面への介入, 行動面への介入, 教育、指導
A40: 46085.708 | B40: 望月弘己 | C40: 香芝生喜病院 | D40: 奈良県 | E40: mochimochihiromi@gmail.com | F40: リハビリテーション室 理学療法士 | G40: 110 | H40: 11 | I40: 7 | J40: 届け出をしておらず、検討もしていない | K40: 関節可動域運動, 筋力増強運動, ポジショニング, 自主運動指導 | L40: 全症例の50％〜74％程度 | M40: 十分な介助 | N40: 全症例の25％〜49％程度 | P40: 全症例の0％〜24％程度 | R40: 全症例の0％〜24％程度 | T40: 握力, 膝伸展筋力, FIM | V40: 握力 | X40: 実施していない | Y40: 知識が不十分 | Z40: FIM | AB40: MMSE, HDS-R | AD40: 深部感覚評価, 認知機能, 注意障害, せん妄, 転倒恐怖感, 過去の転倒歴 | AF40: 決まっていない | AI40: 下肢筋力強化, バランス練習, 歩行練習, 歩容改善, 環境調整, 補助具、装具の適正化, 認知面への介入, 行動面への介入, 教育、指導
...

Sheet サマリ作成用
A1: タイムスタンプ | B1: 回答代表者ご氏名 | C1: ご所属施設名 | D1: ご施設の都道府県 | E1: 貴院の理学療法士・作業療法士の代表者メールアドレス | F1: ご所属部署名・職種（任意） | G1: Q1. 2025年1月～12月における大腿骨近位部骨折の症例数を教えてください。（※保存加療症例を含む） | H1: Q2. 2025年1月～12月の期間において、大腿骨近位部骨折を担当した理学療法士（PT）の在籍人数を教えてください。 | I1: Q3. 2025年1月～12月の期間において、大腿骨近位部骨折を担当した作業療法士（OT）の在籍人数を教えてください。 | J1: Q4. 整形外科病棟における「リハビリテーション・栄養・口腔連携体制加算」の算定状況について、令和8年度診療報酬改定の発表前の時点でお答えください。【単一選択】 | K1: Q5. 手術前リハビリテーションで理学療法士または作業療法士が実施している内容を教えてください。【複数選択可】 | L1: Q6. 身体機能（疼痛、筋力低下など）が原因による制限 【4段階評価】 | M1: Q6-1. 「50％〜74％」「75％〜100％」を選択した方にお尋ねします。 →立位が可能になるために貴施設で取り組んでいる対応策を教えてください。【自由記述】 | N1: Q7. 精神・認知機能（認知機能低下、せん妄など）が原因による制限 【4段階評価】 | O1: Q7-1. 「50％〜74％」「75％〜100％」を選択した方にお尋ねします。 →立位が可能になるために貴施設で取り組んでいる対応策を教えてください。【自由記述】 | P1: Q8. 全身状態（呼吸・循環障害、貧血、電解質異常など）が原因による制限 【4段階評価】 | Q1: Q8-1. 「50％〜74％」「75％〜100％」を選択した方にお尋ねします。 →立位が可能になるために貴施設で取り組んでいる対応策を教えてください。【自由記述】 | R1: Q9. 環境的要因（ベッド配置、病室環境、動線などが起因するもの）が原因による制限 【4段階評価】 | S1: Q9-1. 「50％〜74％」「75％〜100％」を選択した方にお尋ねします。 →立位が可能になるために貴施設で取り組んでいる対応策を教えてください。【自由記述】 | T1: Q10． サルコペニアの評価として理学療法士または作業療法士が実施している評価項目を教えてください。 【複数選択可】 | U1: Q10-1 ※「実施していない」を選択した方におたずねします。 → 実施していない理由を教えてください。【自由記述】 | V1: Q11． フレイルの評価として理学療法士または作業療法士が実施している評価項目を教えてください。 【複数選択可】 | W1: Q11-1 ※「実施していない」を選択した方におたずねします。 → 実施していない理由を教えてください。【自由記述】 | X1: Q12． ロコモティブシンドロームの評価として理学療法士または作業療法士が実施している評価項目を教えてください。 【複数選択可】 | Y1: Q12-1 ※「実施していない」を選択した方におたずねします。 → 実施していない理由を教えてください。【自由記述】 | Z1: Q13． ADLの評価として理学療法士または作業療法士が実施している評価項目を教えてください。 【複数選択可】 | AA1: Q13-1 ※「実施していない」を選択した方におたずねします。 → 実施していない理由を教えてください。【自由記述】 | AB1: Q14． 認知機能の評価として理学,作業療法士または言語聴覚士が実施している評価項目を教えてください。 【複数選択可】 | AC1: Q14-1 ※「実施していない」を選択した方におたずねします。 → 実施していない理由を教えてください。【自由記述】 | AD1: Q15． 貴施設のFLS活動の一環として、理学療法士または作業療法士が実施することが施設内で定められている転倒リスク評価項目があれば教えてください。 【複数選択可】 | AE1: Q15-1 ※「実施していない」を選択した方におたずねします。 → 実施していない理由を教えてください。【自由記述】 | AF1: Q15-2 ※「実施している」方におたずねします。 → 評価を実施する時期（術後何日目など）は貴施設のFLS活動として決められていますか。【単一選択】 | AG1: Q15-2-1 ※「決まっている」を選択した方におたずねします。 術後何日目に実施することが決められているか教えてください。【自由記述】 | AH1: Q15-2-2 ※「決まっていない」を選択した方におたずねします。 → 決まっていない理由を教えてください。【自由記述】 | AI1: Q16． 理学療法士または作業療法士が実施している転倒予防策について教えてください。 【複数選択可】 | AJ1: Q16-1 ※「実施していない」を選択した方におたずねします。 → 実施していない理由を教えてください。【自由記述】
A2: 46066.423 | B2: 高野義隆 | C2: 新潟リハビリテーション病院 | D2: 新潟県 | E2: yoshitaka.takano@aiko.or.jp | F2: リハビリテーション部/理学療法士 | G2: 160 | H2: 28 | I2: 18 | J2: 届け出をしておらず、検討もしていない | K2: 関節可動域運動, 筋力増強運動, ポジショニング | L2: 全症例の25％〜49％程度 | N2: 全症例の25％〜49％程度 | P2: 全症例の25％〜49％程度 | R2: 全症例の0％〜24％程度 | T2: 握力, 5回椅子立ち上がりテスト, 歩行速度, SPPB, TUG, 6分間歩行距離 | V2: TUG, 6分間歩行距離, 認知機能 | X2: 実施していない | Y2: 適応となる患者が少ない | Z2: FIM | AB2: MMSE, AMTS | AD2: TUG, SPPB、Functional Reach Test（FRT）, 5回椅子立ち上がりテスト, 認知機能, せん妄, 過去の転倒歴, 既往疾患の有無（脳血管疾患、パーキンソン病など）, 薬剤（向精神薬、降圧薬、利尿薬、ポリファーマシーなど）, ベッド周囲および病室環境 | AF2: 決まっている | AG2: １４日目 | AI2: 下肢筋力強化, バランス練習, 歩行練習, 起立、着座動作練習, 環境調整, 補助具、装具の適正化, 認知面への介入, 教育、指導
A3: 46068.9 | B3: 田中暢一 | C3: ベルランド総合病院 | D3: 大阪府 | E3: goddess.arisa.showmaking@gmail.com | F3: 理学療法室/理学療法士 | G3: 290 | H3: 18 | I3: 8 | J3: 届け出をしておらず、検討もしていない | K3: 関節可動域運動, 筋力増強運動, DVT予防, リラクセーション, ポジショニング, 自主運動指導, 術後リハビリテーションのオリエンテーション | L3: 全症例の0％〜24％程度 | N3: 全症例の0％〜24％程度 | P3: 全症例の0％〜24％程度 | R3: 全症例の0％〜24％程度 | T3: 握力, 開眼片脚立位時間, 下腿周径 | V3: 握力 | X3: ロコモ25（質問票） | Z3: Barthel Index（BI）, FIM | AB3: MMSE, HDS-R | AD3: 開眼片脚立位時間, 認知機能, 過去の転倒歴, SIDE | AF3: 決まっている | AG3: 7日目 | AI3: 下肢筋力強化, バランス練習, 歩行練習, 起立、着座動作練習, 環境調整, 補助具、装具の適正化, 認知面への介入, 教育、指導
A4: 46069.04 | B4: 丸貴仁 | C4: 所沢白翔会病院 | D4: 埼玉県 | E4: t.maru@hakusyoukai.com | F4: リハビリテーション科、事務部／理学療法士 | G4: 60 | H4: 13 | I4: 6 | J4: 届け出はしていないが、現在検討中である | K4: 関節可動域運動, 筋力増強運動, DVT予防, リラクセーション, ポジショニング, 自主運動指導, 術後リハビリテーションのオリエンテーション | L4: 全症例の75％〜100％程度 | M4: 術前リハビリ（受傷前ADL確認含め）、医師等との情報交換 | N4: 全症例の0％〜24％程度 | P4: 全症例の0％〜24％程度 | R4: 全症例の0％〜24％程度 | T4: 握力, 5回椅子立ち上がりテスト, 歩行速度, TUG, 開眼片脚立位時間, 骨格筋量指数（SMI） | V4: Kihon Checklist（基本チェックリスト）, TUG, 認知機能, 抑うつや意欲低下 | X4: 立ち上がりテスト | Z4: Barthel Index（BI）, FIM | AB4: MMSE, AMTS | AD4: 定量的な下肢筋力測定, 開眼片脚立位時間, TUG, 10m歩行速度, 深部感覚評価, 認知機能, 過去の転倒歴, 既往疾患の有無（脳血管疾患、パーキンソン病など）, 薬剤（向精神薬、降圧薬、利尿薬、ポリファーマシーなど）, ベッド周囲および病室環境 | AF4: 決まっている | AG4: 可能となった日 | AI4: 下肢筋力強化, バランス練習, 歩行練習, 歩容改善, 起立、着座動作練習, 環境調整, 補助具、装具の適正化, 認知面への介入, 薬剤調整, 教育、指導
A5: 46069.136 | B5: 吉井智晴 | C5: 東京医療病院 | D5: 東京都 | E5: c-yoshii@u-ths.ac.jp | F5: リハビリテーション学科 理学療法士 | G5: 100 | H5: 15 | I5: 6 | J5: 現在、算定している | K5: 筋力増強運動, 術後リハビリテーションのオリエンテーション | L5: 全症例の25％〜49％程度 | N5: 全症例の50％〜74％程度 | P5: 全症例の25％〜49％程度 | R5: 全症例の25％〜49％程度 | T5: 握力, 膝伸展筋力 | V5: J-CHS基準, Kihon Checklist（基本チェックリスト） | X5: ロコモ25（質問票） | Z5: Barthel Index（BI） | AB5: HDS-R | AD5: 10m歩行速度 | AF5: 決まっている | AI5: 下肢筋力強化, バランス練習
A6: 46069.461 | B6: 渡邊啓太 | C6: 国家公務員共済組合連合会呉共済病院 | D6: 広島県 | E6: tabe19891204@gmail.com | F6: リハビリテーション科／理学療法士 | G6: 168 | H6: 6 | I6: 8 | J6: 届け出をしておらず、検討もしていない | K6: 関節可動域運動, 筋力増強運動, DVT予防, ポジショニング, 自主運動指導, 術後リハビリテーションのオリエンテーション | L6: 全症例の25％〜49％程度 | N6: 全症例の25％〜49％程度 | P6: 全症例の25％〜49％程度 | R6: 全症例の25％〜49％程度 | T6: 握力, 膝伸展筋力, 歩行速度, 開眼片脚立位時間, 骨格筋量指数（SMI） | V6: 認知機能, 握力 | X6: 実施していない | Z6: Barthel Index（BI）, FIM | AB6: HDS-R, AMTS | AD6: 定量的な下肢筋力測定, 開眼片脚立位時間, 10m歩行速度, 認知機能, 過去の転倒歴 | AF6: 決まっている | AG6: 14日目 | AI6: 下肢筋力強化, バランス練習, 歩行練習, 起立、着座動作練習, 環境調整, 補助具、装具の適正化, 認知面への介入, 教育、指導
A7: 46083.633 | B7: 上原 光司 | C7: 社会医療法人愛仁会 高槻病院 | D7: 大阪府 | E7: uehara.kouji@aijinkai-group.com | F7: リハビリテーション科 理学療法士 | G7: 100 | H7: 25 | I7: 10 | J7: 現在、算定している | K7: 関節可動域運動, 筋力増強運動, 呼吸リハビリテーション, DVT予防, ポジショニング, 自主運動指導, 術後リハビリテーションのオリエンテーション | L7: 全症例の25％〜49％程度 | N7: 全症例の0％〜24％程度 | P7: 全症例の0％〜24％程度 | R7: 全症例の0％〜24％程度 | T7: 膝伸展筋力, 歩行速度, 骨格筋量指数（SMI） | V7: 実施していない | X7: 実施していない | Z7: FIM | AB7: MMSE | AD7: 定量的な下肢筋力測定 | AF7: わからない | AI7: 下肢筋力強化, バランス練習, 歩行練習
A8: 46083.663 | B8: 芝原孝治 | C8: 済生会兵庫県病院 | D8: 兵庫県 | E8: shiba20131946@gmail.com | F8: 芝原孝治 | G8: 146 | H8: 11 | I8: 1 | J8: 届け出はしていないが、現在検討中である | K8: DVT予防, ポジショニング, 自主運動指導, 術後リハビリテーションのオリエンテーション, 認知機能評価 | L8: 全症例の75％〜100％程度 | M8: 基本的に術後翌日は疼痛が強いことが多くパスで端座位までとしており、認知機能低下やせん妄予防のため指示がある際に車椅子移乗まで実施している。 | N8: 全症例の0％〜24％程度 | P8: 全症例の0％〜24％程度 | R8: 全症例の0％〜24％程度 | T8: 5回椅子立ち上がりテスト, 歩行速度, SPPB, TUG, 6分間歩行距離, 下腿周径 | V8: TUG, 6分間歩行距離, 認知機能 | X8: 実施していない | Y8: これまではロコモ外来がなく、リハビリを提供していなかったため | Z8: Barthel Index（BI）, FIM | AB8: MMSE, HDS-R, AMTS | AD8: 定量的な下肢筋力測定, TUG, 10m歩行速度, SPPB、Functional Reach Test（FRT）, 認知機能, 過去の転倒歴, 既往疾患の有無（脳血管疾患、パーキンソン病など）, 薬剤（向精神薬、降圧薬、利尿薬、ポリファーマシーなど）, ベッド周囲および病室環境 | AF8: 決まっている | AG8: 術前1日目にAMTS、転倒歴、既往歴など評価し、術後歩行が可能になった時期に応じて歩行速度など実施。 | AI8: 下肢筋力強化, バランス練習, 歩行練習, 歩容改善, 起立、着座動作練習, 環境調整, 補助具、装具の適正化, 認知面への介入, 行動面への介入, 薬剤調整, 教育、指導
A9: 46083.669 | B9: 中野圭介 | C9: 藤沢市民病院 | D9: 神奈川県 | E9: nakano.k0423@gmail.com | F9: 理学療法士 | G9: 20 | H9: 5 | I9: 0 | J9: 届け出はしていないが、現在検討中である | K9: 実施していない | L9: 全症例の0％〜24％程度 | N9: 全症例の0％〜24％程度 | P9: 全症例の0％〜24％程度 | R9: 全症例の0％〜24％程度 | T9: 実施していない | U9: 栄養面では栄養士がやっている | V9: 実施していない | X9: 実施していない | Y9: 必要を感じていない | Z9: Barthel Index（BI） | AB9: MMSE, HDS-R | AD9: 認知機能, 注意障害, せん妄 | AF9: 決まっていない | AH9: 特に理由はない | AI9: 下肢筋力強化, バランス練習, 歩行練習, 歩容改善, 起立、着座動作練習, 環境調整, 補助具、装具の適正化, 認知面への介入, 行動面への介入, 薬剤調整, 教育、指導
A10: 46083.696 | B10: 寺井 真人 | C10: 社会医療法人蒼生会蒼生病院 | D10: 大阪府 | E10: riha@sousei-hp.jp | F10: リハビリテーション科 作業療法士 | G10: 125 | H10: 9 | I10: 2 | J10: 届け出はしているが、算定していない | K10: 関節可動域運動, 筋力増強運動, 術後リハビリテーションのオリエンテーション | L10: 全症例の0％〜24％程度 | N10: 全症例の50％〜74％程度 | O10: 対策はできていないです。指示が入らず拒否が強いことが多いです。 | P10: 全症例の0％〜24％程度 | R10: 全症例の0％〜24％程度 | T10: 握力, 5回椅子立ち上がりテスト, TUG, 開眼片脚立位時間, MNA-SF | V10: 認知機能, 握力 | X10: 実施していない | Y10: フレイルとサルコペニアで対応しています | Z10: Barthel Index（BI） | AB10: MMSE, AMTS | AD10: 開眼片脚立位時間, TUG, 5回椅子立ち上がりテスト, 認知機能 | AF10: 決まっていない | AH10: 各患者状態が違うため。退院1週前～で評価することが多いです | AI10: 下肢筋力強化, バランス練習, 歩行練習, 歩容改善, 起立、着座動作練習, 環境調整, 補助具、装具の適正化, 認知面への介入, 教育、指導
A11: 46083.705 | B11: 高橋智子 | C11: 国立長寿医療研究センター | D11: 愛知県 | E11: ttomoko@ncgg.go.jp | F11: リハビリテーション科部 理学療法士 | G11: 75 | H11: 9 | I11: 3 | J11: 現在、算定している | K11: 関節可動域運動, リラクセーション, ポジショニング | L11: 全症例の0％〜24％程度 | N11: 全症例の50％〜74％程度 | P11: 全症例の25％〜49％程度 | R11: 全症例の25％〜49％程度 | S11: 初回離床はセラピストが介入するようにし、その場で環境設定をおこないます | T11: 握力, 膝伸展筋力, 歩行速度, SPPB, 骨格筋量指数（SMI）, 下腿周径 | V11: TUG, 認知機能, 握力 | X11: 2ステップテスト | Z11: Barthel Index（BI）, FIM | AB11: MMSE | AD11: TUG, 10m歩行速度, SPPB、Functional Reach Test（FRT）, 認知機能, 注意障害, 過去の転倒歴, SIDE | AF11: 決まっていない | AH11: 疼痛により個人差があるため | AI11: 下肢筋力強化, バランス練習, 歩行練習, 起立、着座動作練習, 環境調整, 補助具、装具の適正化
A12: 46083.738 | B12: 下門 範子 | C12: 北九州総合病院 | D12: 福岡県 | E12: n-shimokado@kitakyu-hp.or.jp | F12: リハビリテーション科/作業療法士 | G12: 247 | H12: 8 | I12: 3 | J12: 届け出はしていないが、現在検討中である | K12: DVT予防, ポジショニング, 自主運動指導, 術後リハビリテーションのオリエンテーション, 離床（例：車椅子移乗,立位,歩行など）, 認知症検査（HDS-R/AMTS） | L12: 全症例の0％〜24％程度 | N12: 全症例の0％〜24％程度 | P12: 全症例の0％〜24％程度 | R12: 全症例の0％〜24％程度 | T12: 下腿周径 | V12: 認知機能 | X12: 立ち上がりテスト | Z12: Barthel Index（BI）, FIM | AB12: MMSE, HDS-R | AD12: 認知機能, ベッド周囲および病室環境 | AF12: 決まっている | AG12: 認知機能評価は術前とENT・転院前です。 | AI12: 下肢筋力強化, バランス練習, 歩行練習, 歩容改善, 起立、着座動作練習, 環境調整, 補助具、装具の適正化, 認知面への介入, 行動面への介入, 薬剤調整, 教育、指導
A13: 46083.865 | B13: 池脇圭司 | C13: 徳島県立中央病院 | D13: 徳島県 | E13: kptaf1117@yahoo.co.jp | F13: リハビリテーション技術科/理学療法士 | G13: 202 | H13: 10 | I13: 6 | J13: 届け出をしておらず、検討もしていない | K13: DVT予防, 自主運動指導, 術後リハビリテーションのオリエンテーション, 離床（例：車椅子移乗,立位,歩行など） | L13: 全症例の75％〜100％程度 | M13: 術後は鎮痛剤を入れて、リハ前に頓服も検討 | N13: 全症例の25％〜49％程度 | P13: 全症例の50％〜74％程度 | Q13: アセスメントし、午前か午後で可能か検討 | R13: 全症例の0％〜24％程度 | T13: 下腿周径, GNRI | V13: 認知機能, GNRI, 握力 | X13: 実施していない | Y13: 術後2週以内には転院になり、評価困難例が多いため | Z13: Barthel Index（BI） | AB13: HDS-R, AMTS | AD13: 開眼片脚立位時間, 認知機能, せん妄, 過去の転倒歴, ベッド周囲および病室環境, SIDE | AF13: 決まっている | AG13: 術後７日目 | AI13: 下肢筋力強化, バランス練習, 歩行練習, 起立、着座動作練習, 環境調整, 教育、指導
A14: 46084.401 | B14: 島岡 秀奉 | C14: 高知県立あき総合病院 | D14: 高知県 | E14: satomi_nonaka@ken2.pref.kochi.lg.jp | G14: 96 | H14: 11 | I14: 5 | J14: 届け出をしておらず、検討もしていない | K14: DVT予防, ポジショニング, 自主運動指導, 術後リハビリテーションのオリエンテーション | L14: 全症例の50％〜74％程度 | M14: 特になし | N14: 全症例の0％〜24％程度 | P14: 全症例の0％〜24％程度 | R14: 全症例の0％〜24％程度 | T14: 握力, 下腿周径 | V14: 認知機能, 握力 | X14: 実施していない | Y14: 回復期のある病院へ転院されることが多く実施できない。 | Z14: Barthel Index（BI）, FIM | AB14: AMTS | AD14: 実施していない | AE14: リハビリ対象の患者が高齢のため大半の患者が転倒リスクが高い | AH14: Q15-1の回答と同様 | AI14: 下肢筋力強化, バランス練習, 歩行練習, 歩容改善, 起立、着座動作練習, 環境調整, 補助具、装具の適正化
A15: 46084.412 | B15: 澤下 浩二 | C15: 甲南医療センタ－ | D15: 兵庫県 | E15: koji.sawashita@kohnan.or.jp | F15: リハビリテーション部/理学療法士 | G15: 146 | H15: 6 | I15: 9 | J15: 届け出はしていないが、現在検討中である | K15: 関節可動域運動, 筋力増強運動, DVT予防, ポジショニング | L15: 全症例の0％〜24％程度 | N15: 全症例の0％〜24％程度 | P15: 全症例の0％〜24％程度 | R15: 全症例の0％〜24％程度 | T15: 握力, 5回椅子立ち上がりテスト, SPPB, 下腿周径 | V15: 握力 | X15: 立ち上がりテスト | Z15: Barthel Index（BI）, FIM | AB15: MMSE | AD15: SPPB、Functional Reach Test（FRT） | AF15: 決まっていない | AI15: 下肢筋力強化, バランス練習, 歩行練習, 環境調整, 補助具、装具の適正化
A16: 46084.415 | B16: 宮澤佑治 | C16: 浜松医療センター | D16: 静岡県 | E16: amakoa@yahoo.co.jp | F16: リハビリテーション技術科/理学療法士 | G16: 350 | H16: 15 | I16: 7 | J16: 届け出をしておらず、検討もしていない | K16: DVT予防, リラクセーション, 離床（例：車椅子移乗,立位,歩行など） | L16: 全症例の75％〜100％程度 | M16: 医師による強力な促しがあります。暴れてうまくいかない人は人数かけて行う事もあります。術翌日は最低座位、車椅子乗車まで行うのが普通でそれができない人は免荷が必要な過体重な人か重度脳卒中併存、暴れるなどの人であることが多いのでそういう人をそこまでするか？は適宜判断して行います。 | N16: 全症例の0％〜24％程度 | P16: 全症例の0％〜24％程度 | Q16: 貧血が原因であれば輸血した後に起立する、短時間にする、起立よりも座位時間確保など | R16: 全症例の0％〜24％程度 | T16: 握力, 歩行速度, 下腿周径 | U16: 人によります。高齢で明らかに弱々しい人は測定しますが元気な人は定型的に行わないこともあります。 | V16: J-CHS基準, 認知機能, 握力 | W16: 頸部骨折にはフレイルが関連している可能性が高いから全例スクリーニングしましょうという高度なことはできていません。各担当者がありそうだな、と感じた場合上記評価を適宜行っています。 | X16: 実施していない | Y16: ロコモティブシンドロームとしては評価スクリーニングしてません。当院ではロコモはそれほど議論されていません。 | Z16: Barthel Index（BI） | AB16: MMSE | AC16: 大腿骨骨折はパス化されていますが近隣のリハビリテーション病院がmmseやらないととらないなどわがままをいうのでよほど元気で認知症扱いするなと怒る人以外はスクリーニングとしてとっています。 | AD16: Berg Balance Scale（BBS）, SPPB、Functional Reach Test（FRT）, せん妄, 過去の転倒歴, 既往疾患の有無（脳血管疾患、パーキンソン病など）, 薬剤（向精神薬、降圧薬、利尿薬、ポリファーマシーなど）, ベッド周囲および病室環境 | AF16: 決まっていない | AH16: 症例数が多すぎるので、院内転倒リスクが高いとnsかリハでおもったひとを抽出して井戸端会議したり転んでしまった人は事案発覚からすぐに集まってカンファします。これも病棟でまちまちなこともあります。 | AI16: 下肢筋力強化, バランス練習, 歩行練習, 歩容改善, 起立、着座動作練習, 環境調整, 補助具、装具の適正化, 教育、指導 | AJ16: 転倒予防策として定型的に行っているものはありません。担当者の裁量で行っていることが多く組織的にできていないのは課題と考えます。組織的に行っていないというのがこの設問の行っていないに該当するのであれば行っていません。
A17: 46084.444 | B17: 水谷純子 | C17: 東京都済生会中央病院 | D17: 東京都 | E17: rh-mizutani@saichu.jp | F17: リハビリテーション技術科／理学療法士 | G17: 78 | H17: 9 | I17: 5 | J17: 届け出をしておらず、検討もしていない | K17: 実施していない | L17: 全症例の0％〜24％程度 | N17: 全症例の0％〜24％程度 | P17: 全症例の0％〜24％程度 | R17: 全症例の0％〜24％程度 | T17: 実施していない | U17: 3次救急で大腿骨近位部骨折の患者にフレイルの評価としては時期的に取っていない。機能評価としてはやっています。 | V17: 実施していない | W17: 3次救急で大腿骨近位部骨折の患者にフレイルの評価としては時期的に取っていない。機能評価としてはやっています。 | X17: 実施していない | Y17: 3次救急で大腿骨近位部骨折の患者であり、評価の時期まで入院していない。 | Z17: Barthel Index（BI） | AB17: MMSE, HDS-R, MoCA, AMTS | AD17: TUG, 10m歩行速度, Berg Balance Scale（BBS）, SPPB、Functional Reach Test（FRT）, 深部感覚評価, 認知機能, せん妄, 過去の転倒歴, 既往疾患の有無（脳血管疾患、パーキンソン病など） | AF17: 決まっている | AG17: TUGは7POD、AMTSは10POD、それ以外は患者に合わせてできる時期に評価 | AI17: 下肢筋力強化, バランス練習, 歩行練習, 歩容改善, 起立、着座動作練習, 環境調整, 補助具、装具の適正化, 認知面への介入, 薬剤調整, 教育、指導
A18: 46084.478 | B18: 望月拓駿 | C18: 静岡県立総合病院 | D18: 静岡県 | E18: omochitack14@gmail.com | F18: リハビリテーション科/理学療法士 | G18: 140 | H18: 25 | I18: 0 | J18: 届け出はしていないが、現在検討中である | K18: 関節可動域運動, 筋力増強運動, DVT予防, 自主運動指導, 術後リハビリテーションのオリエンテーション | L18: 全症例の25％〜49％程度 | N18: 全症例の25％〜49％程度 | P18: 全症例の0％〜24％程度 | R18: 全症例の0％〜24％程度 | T18: 握力, 歩行速度, SPPB | V18: 認知機能, 握力 | X18: 実施していない | Y18: 当院として計測を行っていない | Z18: Barthel Index（BI）, FIM | AB18: MMSE, HDS-R | AD18: TUG, Berg Balance Scale（BBS）, SPPB、Functional Reach Test（FRT）, ベッド周囲および病室環境 | AF18: 決まっていない | AH18: 実際の患者に合わせて可能かどうかを各自判断している | AI18: 下肢筋力強化, バランス練習, 歩行練習, 起立、着座動作練習, 環境調整, 補助具、装具の適正化, 認知面への介入, 行動面への介入
A19: 46084.484 | B19: 三浦大介 | C19: 地方独立行政法人 岐阜県立多治見病院 | D19: 岐阜県 | E19: miura-daisuke@tajimi-hospital.jp | F19: リハビリテーション科 理学療法士 | G19: 159 | H19: 10 | I19: 0 | J19: 届け出をしておらず、検討もしていない | K19: 関節可動域運動, 筋力増強運動, 呼吸リハビリテーション, DVT予防, 自主運動指導, 術後リハビリテーションのオリエンテーション, 離床（例：車椅子移乗,立位,歩行など） | L19: 全症例の50％〜74％程度 | M19: 鎮痛薬による疼痛コントロール 高頻度介入 | N19: 全症例の25％〜49％程度 | P19: 全症例の0％〜24％程度 | R19: 全症例の0％〜24％程度 | T19: SPPB, TUG, 6分間歩行距離 | V19: TUG, 6分間歩行距離, 認知機能 | X19: 実施していない | Z19: Barthel Index（BI） | AB19: HDS-R, AMTS | AD19: TUG, SPPB、Functional Reach Test（FRT）, 認知機能, せん妄, 既往疾患の有無（脳血管疾患、パーキンソン病など）, 薬剤（向精神薬、降圧薬、利尿薬、ポリファーマシーなど）, ベッド周囲および病室環境 | AF19: 決まっている | AG19: 退院時 | AI19: 下肢筋力強化, バランス練習, 歩行練習, 歩容改善, 起立、着座動作練習, 環境調整, 補助具、装具の適正化, 認知面への介入
A20: 46084.56 | B20: 永松 康太 | C20: 神奈川県厚生連 伊勢原協同病院 | D20: 神奈川県 | E20: kotadk.h@gmail.com | F20: リハビリテーション室/理学療法士 | G20: 189 | H20: 7 | I20: 4 | J20: 届け出をしておらず、検討もしていない | K20: 関節可動域運動, 筋力増強運動, DVT予防, リラクセーション, ポジショニング, 自主運動指導, 術後リハビリテーションのオリエンテーション | L20: 全症例の0％〜24％程度 | N20: 全症例の0％〜24％程度 | P20: 全症例の0％〜24％程度 | R20: 全症例の0％〜24％程度 | T20: 膝伸展筋力, 歩行速度 | V20: 認知機能 | X20: 実施していない | Y20: 理由は特にありません | Z20: Barthel Index（BI） | AB20: HDS-R, AMTS | AD20: 定量的な下肢筋力測定, 認知機能, 過去の転倒歴, 既往疾患の有無（脳血管疾患、パーキンソン病など）, 薬剤（向精神薬、降圧薬、利尿薬、ポリファーマシーなど）, ベッド周囲および病室環境 | AF20: 決まっていない | AH20: 通常の理学療法評価の中で行うため、特に決まっていません。 | AI20: 下肢筋力強化, バランス練習, 歩行練習, 歩容改善, 起立、着座動作練習, 環境調整
A21: 46084.577 | B21: 高橋智之 | C21: 関口病院 | D21: 群馬県 | E21: t.takahashi@kouwa-sekiguchi.com | F21: リハビリテーション課/理学療法士 | G21: 189 | H21: 20 | I21: 0 | J21: 届け出をしておらず、検討もしていない | K21: 関節可動域運動, 筋力増強運動, 呼吸リハビリテーション, DVT予防, リラクセーション, ポジショニング, 離床（例：車椅子移乗,立位,歩行など） | L21: 全症例の0％〜24％程度 | N21: 全症例の0％〜24％程度 | P21: 全症例の0％〜24％程度 | R21: 全症例の0％〜24％程度 | T21: 握力, 膝伸展筋力, 5回椅子立ち上がりテスト, 6分間歩行距離, 下腿周径 | V21: 握力 | X21: 立ち上がりテスト | Z21: Barthel Index（BI）, FIM | AB21: HDS-R | AD21: 定量的な下肢筋力測定, 5回椅子立ち上がりテスト, 過去の転倒歴, 既往疾患の有無（脳血管疾患、パーキンソン病など）, 薬剤（向精神薬、降圧薬、利尿薬、ポリファーマシーなど） | AF21: 決まっていない | AH21: 退院前に一回実施するため、患者によって実施するタイミングが異なるから | AI21: 下肢筋力強化, バランス練習, 歩行練習, 歩容改善, 起立、着座動作練習, 環境調整, 行動面への介入, 教育、指導
A22: 46084.581 | B22: 藤野裕気 | C22: 医療法人吉野会はやと整形外科 | D22: 鹿児島県 | E22: hayatoseikei-riha@po2.synapse.ne.jp | F22: リハビリテーション科/理学療法士 | G22: 27 | H22: 7 | I22: 1 | J22: 届け出はしていないが、現在検討中である | K22: 関節可動域運動, 筋力増強運動, DVT予防, リラクセーション, ポジショニング, 自主運動指導, 術後リハビリテーションのオリエンテーション | L22: 全症例の25％〜49％程度 | N22: 全症例の25％〜49％程度 | P22: 全症例の25％〜49％程度 | R22: 全症例の0％〜24％程度 | T22: 握力, 5回椅子立ち上がりテスト, TUG, 開眼片脚立位時間, 下腿周径 | V22: TUG, 握力 | X22: 立ち上がりテスト, 2ステップテスト | Z22: Barthel Index（BI）, FIM | AB22: 実施していない | AC22: 看護師がAMTSまたはHDS-Rを実施している為 | AD22: 開眼片脚立位時間, TUG, 5回椅子立ち上がりテスト, Fall Risk Index | AF22: 決まっていない | AH22: 患者様により立位や歩行できる時期が異なる為 | AI22: 下肢筋力強化, バランス練習, 歩行練習, 歩容改善, 起立、着座動作練習, 環境調整, 補助具、装具の適正化, 行動面への介入, 教育、指導
A23: 46084.592 | B23: 今井智文 | C23: 豊川市民病院 | D23: 愛知県 | E23: reha@toyokawa-ch-aichi.jp | F23: リハビリテーション技術科/理学療法士 | G23: 229 | H23: 18 | I23: 8 | J23: 届け出をしておらず、検討もしていない | K23: 筋力増強運動, DVT予防, リラクセーション, ポジショニング, 自主運動指導, 術後リハビリテーションのオリエンテーション | L23: 全症例の25％〜49％程度 | N23: 全症例の0％〜24％程度 | P23: 全症例の0％〜24％程度 | R23: 全症例の0％〜24％程度 | T23: 実施していない | U23: 術前はベッド上安静で評価実施困難。（座位・起立・歩行は困難）術後は機能回復のための介入が中心となります。 | V23: 実施していない | W23: 術前はベッド上安静で評価実施困難。（座位・起立・歩行は困難）術後は機能回復のための介入が中心となります。 | X23: 実施していない | Y23: 術前はベッド上安静で評価実施困難。（座位・起立・歩行は困難）術後は機能回復のための介入が中心となります。 | Z23: Barthel Index（BI）, FIM | AB23: MMSE, HDS-R, AMTS | AD23: 定量的な下肢筋力測定, 認知機能, 注意障害, ベッド周囲および病室環境, 転倒予防カンファレンスへの参加 | AF23: 決まっている | AG23: 術後３日以内 | AI23: 下肢筋力強化, バランス練習, 歩行練習, 歩容改善, 起立、着座動作練習, 環境調整, 補助具、装具の適正化, 認知面への介入, 行動面への介入, 教育、指導
A24: 46084.595 | B24: 屋宜 秀明 | C24: 徳島市民病院 | D24: 徳島県 | E24: hideaki_rx78@yahoo.co.jp | F24: リハビリテーション科／理学療法士 | G24: 203 | H24: 13 | I24: 0 | J24: 届け出をしておらず、検討もしていない | K24: 関節可動域運動, DVT予防, ポジショニング, 自主運動指導, 術後リハビリテーションのオリエンテーション | L24: 全症例の25％〜49％程度 | N24: 全症例の0％〜24％程度 | P24: 全症例の0％〜24％程度 | R24: 全症例の0％〜24％程度 | T24: 握力, 下腿周径 | V24: 握力 | X24: 実施していない | Z24: Barthel Index（BI） | AB24: MMSE, HDS-R | AD24: 実施していない | AE24: 各セラピストが評価を行い訓練を実施していますが、特定の評価を必須にはしてません。 | AI24: 下肢筋力強化, バランス練習, 歩行練習, 環境調整
A25: 46084.647 | B25: 荒木 裕介 | C25: 医療法人 讃高会 枚方東整形外科病院 | D25: 大阪府 | E25: takai.rihabiri@sankokai.or.jp | F25: リハビリテーション室/理学療法士 | G25: 106 | H25: 9 | I25: 0 | J25: 届け出をしておらず、検討もしていない | K25: 関節可動域運動, 筋力増強運動, リラクセーション, ポジショニング | L25: 全症例の0％〜24％程度 | N25: 全症例の0％〜24％程度 | P25: 全症例の0％〜24％程度 | R25: 全症例の0％〜24％程度 | T25: 握力, 膝伸展筋力, 歩行速度 | V25: 抑うつや意欲低下, 握力 | X25: 実施していない | Z25: Barthel Index（BI）, FIM | AB25: 実施していない | AD25: 実施していない | AE25: 片脚立位等，各々で評価はしているが，施設して定められた評価は無い | AI25: 下肢筋力強化, バランス練習, 歩行練習, 歩容改善, 起立、着座動作練習, 環境調整, 教育、指導
A26: 46084.67 | B26: 堂前 伸 | C26: 東京歯科大学市川総合病院 | D26: 千葉県 | E26: sdoumae@tdc.ac.jp | F26: リハビリテーション科/理学療法士 | G26: 52 | H26: 7 | I26: 0 | J26: 届け出をしておらず、検討もしていない | K26: 術前評価のみ | L26: 全症例の0％〜24％程度 | N26: 全症例の0％〜24％程度 | P26: 全症例の0％〜24％程度 | R26: 全症例の0％〜24％程度 | T26: 握力, 膝伸展筋力, 5回椅子立ち上がりテスト, 歩行速度, TUG, 開眼片脚立位時間, 下腿周径 | V26: TUG, 6分間歩行距離, 認知機能, 握力 | X26: 立ち上がりテスト, ロコモ25（質問票） | Z26: Barthel Index（BI）, FIM | AB26: MMSE, HDS-R | AD26: 認知機能, せん妄, 過去の転倒歴, 既往疾患の有無（脳血管疾患、パーキンソン病など）, 薬剤（向精神薬、降圧薬、利尿薬、ポリファーマシーなど）, ベッド周囲および病室環境 | AF26: 決まっていない | AH26: 動作獲得に個人差があるため、立位・歩行が可能となったタイミングで実施 | AI26: 下肢筋力強化, バランス練習, 歩行練習, 起立、着座動作練習, 環境調整
A27: 46084.692 | B27: 木ノ下哲嗣 | C27: 手稲渓仁会病院 | D27: 北海道 | E27: kinoshita-sat@keijinkai.or.jp | F27: リハビリテーション部/理学療法士 | G27: 70 | H27: 13 | I27: 4 | J27: 届け出をしておらず、検討もしていない | K27: 関節可動域運動, 筋力増強運動, 呼吸リハビリテーション, DVT予防, リラクセーション, ポジショニング, 自主運動指導, 術後リハビリテーションのオリエンテーション, 離床（例：車椅子移乗,立位,歩行など） | L27: 全症例の25％〜49％程度 | N27: 全症例の0％〜24％程度 | P27: 全症例の0％〜24％程度 | R27: 全症例の0％〜24％程度 | T27: 膝伸展筋力, 歩行速度, TUG | V27: J-CHS基準, 認知機能, 抑うつや意欲低下 | X27: 実施していない | Z27: Barthel Index（BI）, FIM | AB27: MMSE, AMTS | AD27: 定量的な下肢筋力測定, TUG, 10m歩行速度, Berg Balance Scale（BBS） | AF27: 決まっている | AG27: 術前もしくは術後１日目 | AI27: 下肢筋力強化, バランス練習, 歩行練習, 歩容改善, 起立、着座動作練習, 環境調整, 認知面への介入
A28: 46084.713 | B28: 山下 麻美 | C28: 済生会長崎病院 | D28: 長崎県 | E28: mami.saisei.0913@gmail.com | F28: リハビリテーション部／理学療法士 | G28: 239 | H28: 14 | I28: 0 | J28: 届け出をしておらず、検討もしていない | K28: 関節可動域運動, 筋力増強運動, DVT予防, リラクセーション, ポジショニング, 自主運動指導, 術後リハビリテーションのオリエンテーション | L28: 全症例の75％〜100％程度 | M28: 術後翌日からのリハビリテーションの介入。 | N28: 全症例の0％〜24％程度 | P28: 全症例の0％〜24％程度 | R28: 全症例の0％〜24％程度 | T28: 実施していない | U28: その他評価で対応。 | V28: 実施していない | W28: その他評価で対応。 | X28: 実施していない | Y28: その他評価で対応。 | Z28: Barthel Index（BI） | AB28: MMSE, HDS-R, MoCA | AD28: 実施していない | AE28: 患者によって、必要な評価を選定して行っている。 | AH28: 同じ病名でも、年齢や性別等患者背景が異なるため。 | AI28: 下肢筋力強化, バランス練習, 歩行練習, 歩容改善, 起立、着座動作練習, 環境調整, 補助具、装具の適正化, 認知面への介入, 行動面への介入, 薬剤調整, 教育、指導
A29: 46084.723 | B29: 岡野宏信 | C29: 香川県立中央病院 | D29: 香川県 | E29: oknhiron@gmail.com | F29: リハビリテーション部/理学療法士 | G29: 138 | H29: 8 | I29: 0 | J29: 届け出をしておらず、検討もしていない | K29: 関節可動域運動, 筋力増強運動, 呼吸リハビリテーション, DVT予防, リラクセーション, ポジショニング, 自主運動指導, 術後リハビリテーションのオリエンテーション | L29: 全症例の25％〜49％程度 | N29: 全症例の25％〜49％程度 | P29: 全症例の25％〜49％程度 | R29: 全症例の0％〜24％程度 | T29: 握力, 歩行速度 | V29: 実施していない | W29: データを利用していないため | X29: 実施していない | Y29: データを利用していないため。 | Z29: Barthel Index（BI） | AB29: AMTS | AD29: 10m歩行速度, | AF29: 決まっている | AG29: 14日目を目安に行っている | AI29: 下肢筋力強化, バランス練習, 歩行練習, 歩容改善, 起立、着座動作練習, 環境調整, 補助具、装具の適正化, 認知面への介入, 行動面への介入, 薬剤調整, 教育、指導
A30: 46084.754 | B30: 藤井千博 | C30: 総合病院 聖隷浜松病院 | D30: 静岡県 | E30: c-fujii@sis.seirei.or.jp | F30: リハビリテーション部／理学療法士 | G30: 211 | H30: 10 | I30: 5 | J30: 届け出はしていないが、現在検討中である | K30: 実施していない | L30: 全症例の0％〜24％程度 | N30: 全症例の0％〜24％程度 | P30: 全症例の0％〜24％程度 | R30: 全症例の0％〜24％程度 | T30: 実施していない | U30: サルコペニアに特化した評価は実施していない 各症例に必要な評価を実施している | V30: 実施していない | W30: フレイルに特化した評価は実施していない 各症例に必要な評価を実施している | X30: 実施していない | Y30: ロコモに特化した評価は実施していない 各症例に必要な評価を実施している | Z30: Barthel Index（BI） | AB30: MMSE, AMTS | AD30: 実施していない | AE30: 活動の一環としては評価は実施していない 各症例に必要な評価を実施している | AI30: 下肢筋力強化, バランス練習, 歩行練習, 歩容改善, 起立、着座動作練習, 環境調整, 補助具、装具の適正化, 認知面への介入, 行動面への介入, 教育、指導
A31: 46084.769 | B31: 那須崇史 | C31: 重工大須病院 | D31: 愛知県 | E31: t-nasu@keimeikai.or.jp | F31: リハビリテーション部/理学療法士 | G31: 176 | H31: 7 | I31: 2 | J31: 現在、算定している | K31: 関節可動域運動, 筋力増強運動, DVT予防, リラクセーション, ポジショニング, 自主運動指導, 術後リハビリテーションのオリエンテーション, 離床（例：車椅子移乗,立位,歩行など）, リアリティーオリエンテーション | L31: 全症例の0％〜24％程度 | N31: 全症例の0％〜24％程度 | P31: 全症例の0％〜24％程度 | R31: 全症例の0％〜24％程度 | T31: 握力, 歩行速度, TUG, 下腿周径 | V31: TUG, 認知機能, 握力 | X31: 実施していない | Y31: ロコモティブシンドロームとしての評価を設定していないため | Z31: Barthel Index（BI）, FIM | AB31: MMSE, MoCA | AD31: 認知機能, 過去の転倒歴, Fall Risk Index | AF31: 決まっている | AG31: 術前に実施しています。 | AI31: 下肢筋力強化, バランス練習, 歩行練習, 歩容改善, 起立、着座動作練習, 環境調整, 補助具、装具の適正化, 認知面への介入, 行動面への介入, 教育、指導
A32: 46084.802 | B32: 青木 敏明 | C32: 東京都立多摩総合医療センター | D32: 東京都 | E32: toshiaki_aoki@tmhp.jp | F32: リハビリテーション科／理学療法士 | G32: 155 | H32: 18 | I32: 0 | J32: 届け出はしていないが、現在検討中である | K32: 関節可動域運動, 筋力増強運動, DVT予防, 術後リハビリテーションのオリエンテーション, 離床（例：車椅子移乗,立位,歩行など） | L32: 全症例の50％〜74％程度 | M32: 痛みの評価・対症療法（軽めのROM・マッサージ等） | N32: 全症例の50％〜74％程度 | O32: 覚醒状態のタイミングをみて介入 | P32: 全症例の50％〜74％程度 | Q32: 起立性低血圧が多く、段階的な姿勢調整とバイタルチェック | R32: 全症例の0％〜24％程度 | T32: 各種評価は行っているが、サルコペニアの評価としては実施していない | U32: 通常の術後評価のみ行っている | V32: 各種評価は行っているが、フレイルの評価としては実施していない | W32: 通常の術後評価のみ行っている | X32: 各種評価は行っているが、ロコモの評価としては実施していない | Y32: 通常の術後評価のみ行っている | Z32: Barthel Index（BI）, FIM | AB32: HDS-R | AD32: 各種評価は行っているが、特に定められた評価としては実施していない | AE32: 通常の評価として実施している | AF32: 決まっていない | AH32: 患者の状況に応じて評価を実施している | AI32: 下肢筋力強化, バランス練習, 歩行練習, 補助具、装具の適正化, 認知面への介入
A33: 46085.259 | B33: 松尾英明 | C33: 福井大学医学部附属病院 | D33: 福井県 | E33: hideakim@u-fukui.ac.jp | F33: リハビリテーション部/理学療法士 | G33: 136 | H33: 4 | I33: 2 | J33: 届け出をしておらず、検討もしていない | K33: 関節可動域運動, 筋力増強運動, DVT予防, ポジショニング, 自主運動指導, 術後リハビリテーションのオリエンテーション, 離床（例：車椅子移乗,立位,歩行など） | L33: 全症例の0％〜24％程度 | N33: 全症例の0％〜24％程度 | P33: 全症例の0％〜24％程度 | R33: 全症例の0％〜24％程度 | T33: SPPB, SARC-F | V33: Kihon Checklist（基本チェックリスト） | X33: 実施していない | Y33: 時間の十分にとれない急性期リハの中で、フレイル、サルコペニアを優先的に評価しているため。 | Z33: FIM | AB33: HDS-R, AMTS | AD33: 開眼片脚立位時間, 10m歩行速度, Berg Balance Scale（BBS）, SPPB、Functional Reach Test（FRT）, 5回椅子立ち上がりテスト, 深部感覚評価, 認知機能, 注意障害, 遂行機能, せん妄, 転倒恐怖感, 過去の転倒歴, 既往疾患の有無（脳血管疾患、パーキンソン病など）, 薬剤（向精神薬、降圧薬、利尿薬、ポリファーマシーなど）, ベッド周囲および病室環境 | AF33: 決まっていない | AH33: もともとの診療活動として行っているため、FLS活動として改めて決め直していない。 | AI33: 下肢筋力強化, バランス練習, 歩行練習, 歩容改善, 起立、着座動作練習, 環境調整, 補助具、装具の適正化, 認知面への介入, 行動面への介入, 薬剤調整, 教育、指導
A34: 46085.507 | B34: 村山智幸 | C34: 新潟厚生連 上越総合病院 | D34: 新潟県 | E34: murayama-itigo-video1@ezweb.ne.jp | F34: リハビリテーション科 理学療法士 | G34: 137 | H34: 12 | I34: 2 | J34: 届け出はしているが、算定していない | K34: DVT予防, リラクセーション, ポジショニング, 自主運動指導, 術後リハビリテーションのオリエンテーション | L34: 全症例の0％〜24％程度 | N34: 全症例の0％〜24％程度 | P34: 全症例の0％〜24％程度 | R34: 全症例の0％〜24％程度 | T34: 握力, 膝伸展筋力 | V34: TUG, 握力 | X34: 立ち上がりテスト | Z34: Barthel Index（BI）, FIM | AB34: MMSE, HDS-R | AD34: 定量的な下肢筋力測定, 過去の転倒歴 | AF34: 決まっている | AG34: 退院までの期間 | AI34: 下肢筋力強化, バランス練習, 歩行練習, 起立、着座動作練習, 環境調整, 補助具、装具の適正化, 認知面への介入
A35: 46085.552 | B35: 藤野 裕美 | C35: 独立行政法人国立病院機構 四国こどもとおとなの医療センター | D35: 香川県 | E35: fujino.hiromi.qm@hosp.go.jp | F35: リハビリテーション科/理学療法士 | G35: 215 | H35: 6 | I35: 0 | J35: 届け出をしておらず、検討もしていない | K35: 実施していない | L35: 全症例の0％〜24％程度 | N35: 全症例の0％〜24％程度 | P35: 全症例の0％〜24％程度 | R35: 全症例の0％〜24％程度 | T35: 実施していない | U35: 評価を活用できる体制が整っておらず、仕組み作りが今後の課題 | V35: 実施していない | W35: 評価を活用できる体制が整っておらず、仕組み作りが今後の課題 | X35: 実施していない | Y35: 評価を活用できる体制が整っておらず、仕組み作りが今後の課題 | Z35: Barthel Index（BI）, FIM | AB35: MMSE, HDS-R | AD35: 定量的な下肢筋力測定, 認知機能, 転倒恐怖感, 過去の転倒歴, ベッド周囲および病室環境 | AF35: 決まっていない | AH35: 症状を基準に評価しており、業務フローは未整備である | AI35: 下肢筋力強化, バランス練習, 歩行練習, 歩容改善, 起立、着座動作練習, 環境調整, 補助具、装具の適正化, 教育、指導
A36: 46085.605 | B36: 桒原 慶太 | C36: 北里大学メディカルセンター | D36: 埼玉県 | E36: kuwabara@insti.kitasato-u.ac.jp | F36: リハビリテーションセンター・理学療法士 | G36: 98 | H36: 6 | I36: 0 | J36: 届け出をしておらず、検討もしていない | K36: 筋力増強運動, ポジショニング, 自主運動指導 | L36: 全症例の0％〜24％程度 | N36: 全症例の0％〜24％程度 | P36: 全症例の0％〜24％程度 | R36: 全症例の0％〜24％程度 | T36: 実施していない | U36: 握力、膝伸展筋力など上記の上から8つ目までは歩ける患者の多くで体力構成要素の検査として実施していますが、「サルコペニア」の評価としては実施していません。 | V36: 実施していない | W36: フレイルの評価をする視点がないため（フレイルであっても急性発症した疾病や手術後の影響が大きいためその視点でのアセスメントはできないため） | X36: 実施していない | Y36: Q11とおなじ理由 | Z36: Barthel Index（BI）, FIM | AB36: MMSE | AD36: 定量的な下肢筋力測定, 開眼片脚立位時間, TUG, 10m歩行速度, 5回椅子立ち上がりテスト, 認知機能 | AF36: 決まっていない | AH36: 日にちではなく、機能状態の改善程度を参考に決めています。 | AI36: 下肢筋力強化, バランス練習, 歩行練習, 歩容改善, 環境調整, 補助具、装具の適正化, 教育、指導
A37: 46085.654 | B37: 坂本 大和 | C37: 社会医療法人大成会 福岡記念病院 | D37: 福岡県 | E37: yappariyoshida@gmail.com | F37: リハビリテーション科／理学療法士 | G37: 225 | H37: 14 | I37: 9 | J37: 届け出をしておらず、検討もしていない | K37: DVT予防, リラクセーション, ポジショニング, 自主運動指導, 術後リハビリテーションのオリエンテーション, 離床（例：車椅子移乗,立位,歩行など）, 全症例には介入しておらず、入院から手術までの待機期間が長くなるケースのみ術前介入している。 | L37: 全症例の25％〜49％程度 | N37: 全症例の25％〜49％程度 | P37: 全症例の0％〜24％程度 | R37: 全症例の0％〜24％程度 | T37: SPPB, 下腿周径, 急性期病院のため、患者が安全に評価できる状況にない。 | V37: 認知機能 | X37: 実施していない | Y37: スタッフの認識と知識がない。 | Z37: Barthel Index（BI） | AB37: MMSE, HDS-R | AD37: 入院前と退院時の屋内、屋外での歩行状況の評価を実施している。 | AF37: 決まっている | AG37: 退院前には、評価項目を入力するようになっている。 | AI37: 下肢筋力強化, バランス練習, 歩行練習, 歩容改善, 環境調整, 補助具、装具の適正化
A38: 46085.675 | B38: 稲井 勲 | C38: 香川県済生会病院 | D38: 香川県 | E38: saiseikaikagawa@mf.pikara.ne.jp | F38: リハビリテーション科理学療法士 | G38: 64 | H38: 10 | I38: 8 | J38: 届け出はしていないが、現在検討中である | K38: 実施していない | L38: 全症例の0％〜24％程度 | N38: 全症例の0％〜24％程度 | P38: 全症例の0％〜24％程度 | R38: 全症例の0％〜24％程度 | T38: 実施していない, | U38: 個人の評価法による | V38: 実施していない | X38: 実施していない | Z38: FIM | AB38: MMSE, HDS-R | AD38: 実施していない | AI38: 下肢筋力強化, バランス練習, 歩行練習, 環境調整
A39: 46085.68 | B39: 照屋俊樹 | C39: 社会医療法人かりゆし会ハートライフ病院 | D39: 沖縄県 | E39: reha@heartlife.or.jp | F39: リハビリテーション科／理学療法士 | G39: 190 | H39: 15 | I39: 5 | J39: 届け出はしていないが、現在検討中である | K39: 関節可動域運動, 筋力増強運動, DVT予防, リラクセーション, ポジショニング, 術後リハビリテーションのオリエンテーション, 離床（例：車椅子移乗,立位,歩行など） | L39: 全症例の50％〜74％程度 | M39: 早期離床行い、動作能力を看護師へ報告し、トイレ誘導の依頼を行っている | N39: 全症例の25％〜49％程度 | P39: 全症例の25％〜49％程度 | R39: 全症例の0％〜24％程度 | T39: 実施していない | U39: 動作能力の改善度合いで評価しているため | V39: 実施していない | W39: 動作能力の改善度合いで評価しているため | X39: 立ち上がりテスト | Z39: FIM | AB39: MMSE, HDS-R | AD39: 注意障害, せん妄, 過去の転倒歴, 既往疾患の有無（脳血管疾患、パーキンソン病など）, 薬剤（向精神薬、降圧薬、利尿薬、ポリファーマシーなど）, ベッド周囲および病室環境 | AF39: 決まっている | AG39: 毎週 | AI39: 下肢筋力強化, バランス練習, 歩行練習, 歩容改善, 起立、着座動作練習, 環境調整, 補助具、装具の適正化, 認知面への介入, 行動面への介入, 教育、指導
A40: 46085.708 | B40: 望月弘己 | C40: 香芝生喜病院 | D40: 奈良県 | E40: mochimochihiromi@gmail.com | F40: リハビリテーション室 理学療法士 | G40: 110 | H40: 11 | I40: 7 | J40: 届け出をしておらず、検討もしていない | K40: 関節可動域運動, 筋力増強運動, ポジショニング, 自主運動指導 | L40: 全症例の50％〜74％程度 | M40: 十分な介助 | N40: 全症例の25％〜49％程度 | P40: 全症例の0％〜24％程度 | R40: 全症例の0％〜24％程度 | T40: 握力, 膝伸展筋力, FIM | V40: 握力 | X40: 実施していない | Y40: 知識が不十分 | Z40: FIM | AB40: MMSE, HDS-R | AD40: 深部感覚評価, 認知機能, 注意障害, せん妄, 転倒恐怖感, 過去の転倒歴 | AF40: 決まっていない | AI40: 下肢筋力強化, バランス練習, 歩行練習, 歩容改善, 環境調整, 補助具、装具の適正化, 認知面への介入, 行動面への介入, 教育、指導
...

Sheet 項目候補
B1: 第1回回答施設の回答率
B2: ご施設の都道府県 （都道府県ごとの分布ランキング形式）
B3: ご施設の都道府県 （地方ごとの分布ランキング形式）
B4: ご施設の都道府県 （都道府県ごとの施設会員数当たり回答率）
B5: ご施設の都道府県 （地方ごとの施設会員数当たり回答率）
B6: ご所属部署名・職種（任意） →分布にて
B7: Q1. 2025年1月～12月における大腿骨近位部骨折の症例数を教えてください。（※保存加療症例を含む）
B8: Q2. 2025年1月～12月の期間において、大腿骨近位部骨折を担当した理学療法士（PT）の在籍人数を教えてください。
B9: Q3. 2025年1月～12月の期間において、大腿骨近位部骨折を担当した作業療法士（OT）の在籍人数を教えてください。
B10: Q4. 整形外科病棟における「リハビリテーション・栄養・口腔連携体制加算」の算定状況について、令和8年度診療報酬改定の発表前の時点でお答えください。【単一選択】
B11: Q5. 手術前リハビリテーションで理学療法士または作業療法士が実施している内容を教えてください。【複数選択可】
B12: Q6. 身体機能（疼痛、筋力低下など）が原因による制限 【4段階評価】
... B36: Q16-1 ※「実施していない」を選択した方におたずねします。 → 実施していない理由を教えてください。【自由記述】

Sheet グラフ作成用シート
A1: 新潟県 | G1: 地方別回答施設数 | I1: 地方別施設会員数 | J1: 地方別回答率 | M1: 都道府県別回答数 | N1: 施設会員数 | O1: 都道府県別回答率
A2: 大阪府 | C2: 列1 | D2: 列2 | F2: 北海道 | G2: 12 | H2: =G2/$G$11 | I2: 31 | J2: =G2/I2 | L2: 北海道 | M2: 12 | N2: 31 | O2: =M2/N2
A3: 埼玉県 | C3: 北海道 | D3: =COUNTIF(A:A,C3) | F3: 東北 | G3: 22 | H3: =G3/$G$11 | I3: 44 | J3: =G3/I3 | L3: 青森県 | M3: 6 | N3: 9 | O3: =M3/N3
A4: 東京都 | C4: 青森県 | D4: =COUNTIF(A:A,C4) | F4: 関東 | G4: 56 | H4: =G4/$G$11 | I4: 160 | J4: =G4/I4 | L4: 岩手県 | M4: 1 | N4: 1 | O4: =M4/N4
A5: 広島県 | C5: 岩手県 | D5: =COUNTIF(A:A,C5) | F5: 中部 | G5: 63 | H5: =G5/$G$11 | I5: 143 | J5: =G5/I5 | L5: 宮城県 | M5: 4 | N5: 11 | O5: =M5/N5
A6: 大阪府 | C6: 宮城県 | D6: =COUNTIF(A:A,C6) | F6: 近畿 | G6: 62 | H6: =G6/$G$11 | I6: 139 | J6: =G6/I6 | L6: 秋田県 | M6: 2 | N6: 8 | O6: =M6/N6
A7: 兵庫県 | C7: 秋田県 | D7: =COUNTIF(A:A,C7) | F7: 中国 | G7: 21 | H7: =G7/$G$11 | I7: 50 | J7: =G7/I7 | L7: 山形県 | M7: 2 | N7: 7 | O7: =M7/N7
A8: 神奈川県 | C8: 山形県 | D8: =COUNTIF(A:A,C8) | F8: 四国 | G8: 16 | H8: =G8/$G$11 | I8: 34 | J8: =G8/I8 | L8: 福島県 | M8: 7 | N8: 8 | O8: =M8/N8
A9: 大阪府 | C9: 福島県 | D9: =COUNTIF(A:A,C9) | F9: 九州 | G9: 33 | H9: =G9/$G$11 | I9: 88 | J9: =G9/I9 | L9: 茨城県 | M9: 4 | N9: 14 | O9: =M9/N9
A10: 愛知県 | C10: 茨城県 | D10: =COUNTIF(A:A,C10) | F10: 沖縄 | G10: 4 | H10: =G10/$G$11 | I10: 10 | J10: =G10/I10 | L10: 栃木県 | M10: 4 | N10: 6 | O10: =M10/N10
A11: 福岡県 | C11: 栃木県 | D11: =COUNTIF(A:A,C11) | G11: =SUM(G1:G10) | H11: =SUM(H1:H10) | I11: =SUM(I1:I10) | J11: =G11/I11 | K11: ←全体の回答率 | L11: 群馬県 | M11: 1 | N11: 10 | O11: =M11/N11
A12: 徳島県 | C12: 群馬県 | D12: =COUNTIF(A:A,C12) | L12: 埼玉県 | M12: 11 | N12: 29 | O12: =M12/N12
A13: 高知県 | C13: 埼玉県 | D13: =COUNTIF(A:A,C13) | L13: 千葉県 | M13: 10 | N13: 23 | O13: =M13/N13
A14: 兵庫県 | C14: 千葉県 | D14: =COUNTIF(A:A,C14) | L14: 東京都 | M14: 13 | N14: 43 | O14: =M14/N14
A15: 静岡県 | C15: 東京都 | D15: =COUNTIF(A:A,C15) | L15: 神奈川県 | M15: 13 | N15: 35 | O15: =M15/N15
A16: 東京都 | C16: 神奈川県 | D16: =COUNTIF(A:A,C16) | G16: ご所属部署名・職種（任意） | L16: 新潟県 | M16: 5 | N16: 17 | O16: =M16/N16
A17: 静岡県 | C17: 新潟県 | D17: =COUNTIF(A:A,C17) | G17: リハビリテーションセンター 理学療法学科 理学療法士 | H17: リハビリテーション科（室・課・部・センターも含む） | L17: 富山県 | M17: 5 | N17: 9 | O17: =M17/N17
A18: 岐阜県 | C18: 富山県 | D18: =COUNTIF(A:A,C18) | G18: リハビリテーションセンター／理学療法士 | H18: 理学療法士 | L18: 石川県 | M18: 3 | N18: 8 | O18: =M18/N18
A19: 神奈川県 | C19: 石川県 | D19: =COUNTIF(A:A,C19) | G19: リハビリテーションセンター／理学療法士 | H19: 作業療法士 | L19: 福井県 | M19: 2 | N19: 7 | O19: =M19/N19
A20: 群馬県 | C20: 福井県 | D20: =COUNTIF(A:A,C20) | G20: リハビリテーションセンター/理学療法士 | H20: その他 | L20: 山梨県 | M20: 2 | N20: 4 | O20: =M20/N20
A21: 鹿児島県 | C21: 山梨県 | D21: =COUNTIF(A:A,C21) | G21: リハビリテーションセンター/理学療法士 | H21: Q1. 2025年1月～12月における大腿骨近位部骨折の症例数を教えてください。（※保存加療症例を含む） | L21: 長野県 | M21: 5 | N21: 14 | O21: =M21/N21
A22: 愛知県 | C22: 長野県 | D22: =COUNTIF(A:A,C22) | G22: リハビリテーションセンター・理学療法士 | H22: 2972 | I22: MIN | L22: 岐阜県 | M22: 9 | N22: 14 | O22: =M22/N22
A23: 徳島県 | C23: 岐阜県 | D23: =COUNTIF(A:A,C23) | G23: リハビリテーションぶ／理学療法士 | H23: 1660 | I23: MAX | L23: 静岡県 | M23: 12 | N23: 24 | O23: =M23/N23
A24: 大阪府 | C24: 静岡県 | D24: =COUNTIF(A:A,C24) | G24: リハビリテーション科 | H24: 996 | I24: MED | L24: 愛知県 | M24: 20 | N24: 46 | O24: =M24/N24
A25: 千葉県 | C25: 愛知県 | D25: =COUNTIF(A:A,C25) | G25: リハビリテーション科 | H25: 826 | I25: AVG | L25: 三重県 | M25: 9 | N25: 13 | O25: =M25/N25
A26: 北海道 | C26: 三重県 | D26: =COUNTIF(A:A,C26) | G26: リハビリテーション科 作業療法士 | H26: 683 | I26: 区間 | J26: 施設数 | K26: 累積% | L26: 滋賀県 | M26: 3 | N26: 13 | O26: =M26/N26
A27: 長崎県 | C27: 滋賀県 | D27: =COUNTIF(A:A,C27) | G27: リハビリテーション科 作業療法士 | H27: 606 | I27: ~25 | J27: =COUNTIF(テーブル6[Q1. 2025年1月～12月における大腿骨近位部骨折の症例数を教えてください。（※保存加療症例を含む）],"<25") | K27: =J27/SUM($J$27:$J$39) | L27: 京都府 | M27: 7 | N27: 16 | O27: =M27/N27
A28: 香川県 | C28: 京都府 | D28: =COUNTIF(A:A,C28) | G28: リハビリテーション科 作業療法士 | H28: 500 | I28: 25~50 | J28: =COUNTIFS(テーブル6[Q1. 2025年1月～12月における大腿骨近位部骨折の症例数を教えてください。（※保存加療症例を含む）],">=25",テーブル6[Q1. 2025年1月～12月における大腿骨近位部骨折の症例数を教えてください。（※保存加療症例を含む）],"<50") | K28: =K27+J28/SUM($J$27:$J$39) | L28: 大阪府 | M28: 24 | N28: 49 | O28: =M28/N28
